Workbook

Sheet Capa
A1: LOGO CLIENTE | D1: NÚMERO INFRAS:
D2: IFS-2226-020-G-LD-00001
D3: NÚMERO CLIENTE
D4: --
A5: PROJETO CONCEITUAL/BÁSICO/EXECUTIVO EXEMPLO (NOME DO PORTO) EXEMPLO (PROJETO DE DRAGAGEM) LISTA DE DOCUMENTOS | L5: REV:
L6: 1
L7: FOLHA:
A10: CONTROLE DE REVISÕES
A11: TIPO DE EMISSÃO (T.E.) | C11: (A) PRELIMINAR | F11: (D) PARA COTAÇÃO | J11: (G) CONFORME CONSTRUÍDO
C12: (B) PARA COMENTÁRIOS | F12: (E) PARA CONSTRUÇÃO | J12: (H) CANCELADO
C13: (C) PARA CONHECIMENTO | F13: (F) CONFORME COMPRADO | J13: (I) APROVADO
A15: REV. | B15: T.E. | C15: DESCRIÇÃO
A16: 0 | B16: C | C16: IFS-GRD-2226-001
A17: 1 | B17: C | C17: IFS-GRD-9999-002
C31: REV. 0 | E31: REV. 1 | G31: REV. 2 | H31: REV. 3 | K31: REV. 4
A32: DATA | C32: 13/03/26 | E32: 10/06/26
A33: EXECUÇÃO | C33: PAM | E33: ABC
A34: VERIFICAÇÃO | C34: XXX | E34: DEF
A35: APROVAÇÃO | C35: XXX | E35: GHI
C36: REV. 5 | E36: REV. 6 | G36: REV. 7 | H36: REV. 8 | K36: REV. 9
A37: DATA
A38: EXECUÇÃO
A39: VERIFICAÇÃO
A40: APROVAÇÃO
A42: AS INFORMAÇÕES DESTE DOCUMENTO SÃO DE PROPRIEDADE DA INFRAS ENGENHARIA, SENDO PROIBIDA SUA UTILIZAÇÃO FORA DA SUA FINALIDADE SEM UMA PRÉVIA AUTORIZAÇÃO.
A44: WWW.INFRAS.COM.BR - CONTATO@IINFRAS.COM.BR RUA HERMANN BLUMENAU, 110 – CENTRO – 88020-020 – FLORIANÓPOLIS-SC

Sheet LD
B1: LOGO CLIENTE | C1: NÚMERO INFRAS ENGENHARIA
C2: =+Capa!D2
C3: NÚMERO CLIENTE
C4: =+Capa!D4
B5: =+Capa!A5 | J5: REV.
J6: =+Capa!L6
J7: PÁGINA
J8: 1
B10: TIPO DE EMISSÃO: | C10: (A) PRELIMINAR (B) PARA COMENTÁRIOS (C) PARA CONHECIMENTO (D) PARA COTAÇÃO (E) PARA CONSTRUÇÃO (F) CONFORME COMPRADO (G) CONFORME CONSTRUIDO (H) CANCELADO (I) APROVADO | K10: 0 | O10: 1 | S10: 2 | W10: 3 | AA10: 4 | AE10: 5 | AI10: 6 | AM10: 7 | AQ10: 8 | AU10: 9 | AY10: 10 | BC10: 11
K11: EMISSÃO INICIAL | O11: REVISÃO 01 | S11: REVISÃO 02 | W11: REVISÃO 03 | AA11: REVISÃO 04 | AE11: REVISÃO 05 | AI11: REVISÃO 06 | AM11: REVISÃO 07 | AQ11: REVISÃO 08 | AU11: REVISÃO 09 | AY11: REVISÃO 10 | BC11: REVISÃO 11 | BZ11: GRD | CA11: 001 | CB11: 002 | CC11: 003 | CD11: 004 | CE11: 005 | CF11: 006 | CG11: 007 | CH11: 008 | CI11: 009 | CJ11: 010 | CK11: 011 | CL11: 012 | CM11: 013 | CN11: 014 | CO11: 015 | CP11: 016 | CQ11: 017 | CR11: 018 | CS11: 019 | CT11: 020 | CU11: 021 | CV11: 022 | CW11: 023 | CX11: 024 | CY11: 025 | CZ11: 026 | DA11: 027 | DB11: 028 | DC11: 029 | DD11: 030 | DE11: 031 | DF11: 032 | DG11: 033 | DH11: 034 | DI11: 035 | DJ11: 036 | DK11: 037 | DL11: 038 | DM11: 039 | DN11: 040 | DO11: 041 | DP11: 042 | DQ11: 043 | DR11: 044 | DS11: 045 | DT11: 046 | DU11: 047 | DV11: 048 | DW11: 049 | DX11: 050 | DY11: 051 | DZ11: 052 | EA11: 053 | EB11: 054 | EC11: 055 | ED11: 056 | EE11: 057 | EF11: 058 | EG11: 059 | EH11: 060 | EI11: 061 | EJ11: 062 | EK11: 063 | EL11: 064 | EM11: 065 | EN11: 066 | EO11: 067 | EP11: 068 | EQ11: 069 | ER11: 070 | ES11: 071 | ET11: 072 | EU11: 073 | EV11: 074 | EW11: 075 | EX11: 076 | EY11: 077 | EZ11: 078 | FA11: 079 | FB11: 080 | FC11: 081 | FD11: 082 | FE11: 083 | FF11: 084 | FG11: 085 | FH11: 086 | FI11: 087 | FJ11: 088 | FK11: 089 | FL11: 090 | FM11: 091 | FN11: 092 | FO11: 093 | FP11: 094 | FQ11: 095 | FR11: 096 | FS11: 097 | FT11: 098 | FU11: 099 | FV11: 100
B12: NÚMERO INFRAS | C12: TÍTULO | D12: REV. | E12: T. E. | F12: GRD | G12: DATA | H12: PÁGS/ FOLHAS | I12: FORMATO | J12: A1 EQUIV. | K12: REV. | L12: T. E. | M12: GRD | N12: DATA | O12: REV. | P12: T. E. | Q12: GRD | R12: DATA | S12: REV. | T12: T. E. | U12: GRD | V12: DATA | W12: REV. | X12: T. E. | Y12: GRD | Z12: DATA | AA12: REV. | AB12: T. E. | AC12: GRD | AD12: DATA | AE12: REV. | AF12: T. E. | AG12: GRD | AH12: DATA | AI12: REV. | AJ12: T. E. | AK12: GRD | AL12: DATA | AM12: REV. | AN12: T. E. | AO12: GRD | AP12: DATA | AQ12: REV. | AR12: T. E. | AS12: GRD | AT12: DATA | AU12: REV. | AV12: T. E. | AW12: GRD | AX12: DATA | AY12: REV. | AZ12: T. E. | BA12: GRD | BB12: DATA | BC12: REV. | BD12: T. E. | BE12: GRD | BF12: DATA
B13: GERAL
B14: IFS-3312-123-D-DC-00001 | D14: =IF(K14="","",MAX($CA14:$FV14)) | E14: {=IF($K14="","",OFFSET($A$1,ROW($B14)-1,11+$D14*4,))} | F14: {=IF($K14="","",OFFSET($A$1,ROW($B14)-1,12+$D14*4,))} | G14: {=IF($K14="","",OFFSET($A$1,ROW($B14)-1,13+$D14*4,))} | J14: =IF(I14="A4",H14/8,IF(I14="A3",H14/4,IF(I14="A2",H14/2,IF(I14="A1",H14/1,IF(I14="A0",H14*2,""))))) | K14: {=IFERROR(OFFSET($BZ$11,ROW($B14)-11,MATCH(K$10,$CA14:$FV14,0),),"")} | L14: =IF(K14="","",IF(VLOOKUP($B14,INDIRECT("'GRD-"&M14&"'!$B:$R"),16,FALSE)="","",VLOOKUP($B14,INDIRECT("'GRD-"&M14&"'!$B:$R"),16,FALSE))) | M14: {=IF(K14="","",IFERROR(OFFSET($BZ$11,0,MATCH($K14,$CA14:$FV14,0),),""))} | N14: {=IF(K14="","",INDIRECT("'GRD-"&M14&"'!$L$7"))} | O14: {=IFERROR(OFFSET($BZ$11,ROW($B14)-11,MATCH(O$10,$CA14:$FV14,0),),"")} | P14: =IF(O14="","",IF(VLOOKUP($B14,INDIRECT("'GRD-"&Q14&"'!$B:$R"),16,FALSE)="","",VLOOKUP($B14,INDIRECT("'GRD-"&Q14&"'!$B:$R"),16,FALSE))) | Q14: {=IF(O14="","",IFERROR(OFFSET($BZ$11,0,MATCH($O14,$CA14:$FV14,0),),""))} | R14: {=IF(O14="","",INDIRECT("'GRD-"&Q14&"'!$L$7"))} | S14: {=IFERROR(OFFSET($BZ$11,ROW($B14)-11,MATCH(S$10,$CA14:$FV14,0),),"")} | T14: =IF(S14="","",IF(VLOOKUP($B14,INDIRECT("'GRD-"&U14&"'!$B:$R"),16,FALSE)="","",VLOOKUP($B14,INDIRECT("'GRD-"&U14&"'!$B:$R"),16,FALSE))) | U14: {=IF(S14="","",IFERROR(OFFSET($BZ$11,0,MATCH($S14,$CA14:$FV14,0),),""))} | V14: {=IF(S14="","",INDIRECT("'GRD-"&U14&"'!$L$7"))} | W14: {=IFERROR(OFFSET($BZ$11,ROW($B14)-11,MATCH(W$10,$CA14:$FV14,0),),"")} | X14: =IF(W14="","",IF(VLOOKUP($B14,INDIRECT("'GRD-"&Y14&"'!$B:$R"),16,FALSE)="","",VLOOKUP($B14,INDIRECT("'GRD-"&Y14&"'!$B:$R"),16,FALSE))) | Y14: {=IF(W14="","",IFERROR(OFFSET($BZ$11,0,MATCH($W14,$CA14:$FV14,0),),""))} | Z14: {=IF(W14="","",INDIRECT("'GRD-"&Y14&"'!$L$7"))} | AA14: {=IFERROR(OFFSET($BZ$11,ROW($B14)-11,MATCH(AA$10,$CA14:$FV14,0),),"")} | AB14: =IF(AA14="","",IF(VLOOKUP($B14,INDIRECT("'GRD-"&AC14&"'!$B:$R"),16,FALSE)="","",VLOOKUP($B14,INDIRECT("'GRD-"&AC14&"'!$B:$R"),16,FALSE))) | AC14: {=IF(AA14="","",IFERROR(OFFSET($BZ$11,0,MATCH($AA14,$CA14:$FV14,0),),""))} | AD14: {=IF(AA14="","",INDIRECT("'GRD-"&AC14&"'!$L$7"))} | AE14: {=IFERROR(OFFSET($BZ$11,ROW($B14)-11,MATCH(AE$10,$CA14:$FV14,0),),"")} | AF14: =IF(AE14="","",IF(VLOOKUP($B14,INDIRECT("'GRD-"&AG14&"'!$B:$R"),16,FALSE)="","",VLOOKUP($B14,INDIRECT("'GRD-"&AG14&"'!$B:$R"),16,FALSE))) | AG14: {=IF(AE14="","",IFERROR(OFFSET($BZ$11,0,MATCH($AE14,$CA14:$FV14,0),),""))} | AH14: {=IF(AE14="","",INDIRECT("'GRD-"&AG14&"'!$L$7"))} | AI14: {=IFERROR(OFFSET($BZ$11,ROW($B14)-11,MATCH(AI$10,$CA14:$FV14,0),),"")} | AJ14: =IF(AI14="","",IF(VLOOKUP($B14,INDIRECT("'GRD-"&AK14&"'!$B:$R"),16,FALSE)="","",VLOOKUP($B14,INDIRECT("'GRD-"&AK14&"'!$B:$R"),16,FALSE))) | AK14: {=IF(AI14="","",IFERROR(OFFSET($BZ$11,0,MATCH($AI14,$CA14:$FV14,0),),""))} | AL14: {=IF(AI14="","",INDIRECT("'GRD-"&AK14&"'!$L$7"))} | AM14: {=IFERROR(OFFSET($BZ$11,ROW($B14)-11,MATCH(AM$10,$CA14:$FV14,0),),"")} | AN14: =IF(AM14="","",IF(VLOOKUP($B14,INDIRECT("'GRD-"&AO14&"'!$B:$R"),16,FALSE)="","",VLOOKUP($B14,INDIRECT("'GRD-"&AO14&"'!$B:$R"),16,FALSE))) | AO14: {=IF(AM14="","",IFERROR(OFFSET($BZ$11,0,MATCH($AM14,$CA14:$FV14,0),),""))} | AP14: {=IF(AM14="","",INDIRECT("'GRD-"&AO14&"'!$L$7"))} | AQ14: {=IFERROR(OFFSET($BZ$11,ROW($B14)-11,MATCH(AQ$10,$CA14:$FV14,0),),"")} | AR14: =IF(AQ14="","",IF(VLOOKUP($B14,INDIRECT("'GRD-"&AS14&"'!$B:$R"),16,FALSE)="","",VLOOKUP($B14,INDIRECT("'GRD-"&AS14&"'!$B:$R"),16,FALSE))) | AS14: {=IF(AQ14="","",IFERROR(OFFSET($BZ$11,0,MATCH($AQ14,$CA14:$FV14,0),),""))} | AT14: {=IF(AQ14="","",INDIRECT("'GRD-"&AS14&"'!$L$7"))} | AU14: {=IFERROR(OFFSET($BZ$11,ROW($B14)-11,MATCH(AU$10,$CA14:$FV14,0),),"")} | AV14: =IF(AU14="","",IF(VLOOKUP($B14,INDIRECT("'GRD-"&AW14&"'!$B:$R"),16,FALSE)="","",VLOOKUP($B14,INDIRECT("'GRD-"&AW14&"'!$B:$R"),16,FALSE))) | AW14: {=IF(AU14="","",IFERROR(OFFSET($BZ$11,0,MATCH($AU14,$CA14:$FV14,0),),""))} | AX14: {=IF(AU14="","",INDIRECT("'GRD-"&AW14&"'!$L$7"))} | AY14: {=IFERROR(OFFSET($BZ$11,ROW($B14)-11,MATCH(AY$10,$CA14:$FV14,0),),"")} | AZ14: =IF(AY14="","",IF(VLOOKUP($B14,INDIRECT("'GRD-"&BA14&"'!$B:$R"),16,FALSE)="","",VLOOKUP($B14,INDIRECT("'GRD-"&BA14&"'!$B:$R"),16,FALSE))) | BA14: {=IF(AY14="","",IFERROR(OFFSET($BZ$11,0,MATCH($AY14,$CA14:$FV14,0),),""))} | BB14: {=IF(AY14="","",INDIRECT("'GRD-"&BA14&"'!$L$7"))} | BC14: {=IFERROR(OFFSET($BZ$11,ROW($B14)-11,MATCH(BC$10,$CA14:$FV14,0),),"")} | BD14: =IF(BC14="","",IF(VLOOKUP($B14,INDIRECT("'GRD-"&BE14&"'!$B:$R"),16,FALSE)="","",VLOOKUP($B14,INDIRECT("'GRD-"&BE14&"'!$B:$R"),16,FALSE))) | BE14: {=IF(BC14="","",IFERROR(OFFSET($BZ$11,0,MATCH($BC14,$CA14:$FV14,0),),""))} | BF14: {=IF(BC14="","",INDIRECT("'GRD-"&BE14&"'!$L$7"))} | CA14: =IFERROR(VLOOKUP($B14,INDIRECT("'GRD-"&CA$11&"'!B:R"),15,FALSE),"") | CB14: =IFERROR(VLOOKUP($B14,INDIRECT("'GRD-"&CB$11&"'!B:R"),15,FALSE),"") | CC14: =IFERROR(VLOOKUP($B14,INDIRECT("'GRD-"&CC$11&"'!B:R"),15,FALSE),"") | CD14: =IFERROR(VLOOKUP($B14,INDIRECT("'GRD-"&CD$11&"'!B:R"),15,FALSE),"") | CE14: =IFERROR(VLOOKUP($B14,INDIRECT("'GRD-"&CE$11&"'!B:R"),15,FALSE),"") | CF14: =IFERROR(VLOOKUP($B14,INDIRECT("'GRD-"&CF$11&"'!B:R"),15,FALSE),"") | CG14: =IFERROR(VLOOKUP($B14,INDIRECT("'GRD-"&CG$11&"'!B:R"),15,FALSE),"") | CH14: =IFERROR(VLOOKUP($B14,INDIRECT("'GRD-"&CH$11&"'!B:R"),15,FALSE),"") | ... FV14: =IFERROR(VLOOKUP($B14,INDIRECT("'GRD-"&FV$11&"'!B:R"),15,FALSE),"")
B15: LISTE OS DOCUMENTOS AQUI... | D15: =IF(K15="","",MAX($CA15:$FV15)) | E15: {=IF($K15="","",OFFSET($A$1,ROW($B15)-1,11+$D15*4,))} | F15: {=IF($K15="","",OFFSET($A$1,ROW($B15)-1,12+$D15*4,))} | G15: {=IF($K15="","",OFFSET($A$1,ROW($B15)-1,13+$D15*4,))} | J15: =IF(I15="A4",H15/8,IF(I15="A3",H15/4,IF(I15="A2",H15/2,IF(I15="A1",H15/1,IF(I15="A0",H15*2,""))))) | K15: {=IFERROR(OFFSET($BZ$11,ROW($B15)-11,MATCH(K$10,$CA15:$FV15,0),),"")} | L15: =IF(K15="","",IF(VLOOKUP($B15,INDIRECT("'GRD-"&M15&"'!$B:$R"),16,FALSE)="","",VLOOKUP($B15,INDIRECT("'GRD-"&M15&"'!$B:$R"),16,FALSE))) | M15: {=IF(K15="","",IFERROR(OFFSET($BZ$11,0,MATCH($K15,$CA15:$FV15,0),),""))} | N15: {=IF(K15="","",INDIRECT("'GRD-"&M15&"'!$L$7"))} | O15: {=IFERROR(OFFSET($BZ$11,ROW($B15)-11,MATCH(O$10,$CA15:$FV15,0),),"")} | P15: =IF(O15="","",IF(VLOOKUP($B15,INDIRECT("'GRD-"&Q15&"'!$B:$R"),16,FALSE)="","",VLOOKUP($B15,INDIRECT("'GRD-"&Q15&"'!$B:$R"),16,FALSE))) | Q15: {=IF(O15="","",IFERROR(OFFSET($BZ$11,0,MATCH($O15,$CA15:$FV15,0),),""))} | R15: {=IF(O15="","",INDIRECT("'GRD-"&Q15&"'!$L$7"))} | S15: {=IFERROR(OFFSET($BZ$11,ROW($B15)-11,MATCH(S$10,$CA15:$FV15,0),),"")} | T15: =IF(S15="","",IF(VLOOKUP($B15,INDIRECT("'GRD-"&U15&"'!$B:$R"),16,FALSE)="","",VLOOKUP($B15,INDIRECT("'GRD-"&U15&"'!$B:$R"),16,FALSE))) | U15: {=IF(S15="","",IFERROR(OFFSET($BZ$11,0,MATCH($S15,$CA15:$FV15,0),),""))} | V15: {=IF(S15="","",INDIRECT("'GRD-"&U15&"'!$L$7"))} | W15: {=IFERROR(OFFSET($BZ$11,ROW($B15)-11,MATCH(W$10,$CA15:$FV15,0),),"")} | X15: =IF(W15="","",IF(VLOOKUP($B15,INDIRECT("'GRD-"&Y15&"'!$B:$R"),16,FALSE)="","",VLOOKUP($B15,INDIRECT("'GRD-"&Y15&"'!$B:$R"),16,FALSE))) | Y15: {=IF(W15="","",IFERROR(OFFSET($BZ$11,0,MATCH($W15,$CA15:$FV15,0),),""))} | Z15: {=IF(W15="","",INDIRECT("'GRD-"&Y15&"'!$L$7"))} | AA15: {=IFERROR(OFFSET($BZ$11,ROW($B15)-11,MATCH(AA$10,$CA15:$FV15,0),),"")} | AB15: =IF(AA15="","",IF(VLOOKUP($B15,INDIRECT("'GRD-"&AC15&"'!$B:$R"),16,FALSE)="","",VLOOKUP($B15,INDIRECT("'GRD-"&AC15&"'!$B:$R"),16,FALSE))) | AC15: {=IF(AA15="","",IFERROR(OFFSET($BZ$11,0,MATCH($AA15,$CA15:$FV15,0),),""))} | AD15: {=IF(AA15="","",INDIRECT("'GRD-"&AC15&"'!$L$7"))} | AE15: {=IFERROR(OFFSET($BZ$11,ROW($B15)-11,MATCH(AE$10,$CA15:$FV15,0),),"")} | AF15: =IF(AE15="","",IF(VLOOKUP($B15,INDIRECT("'GRD-"&AG15&"'!$B:$R"),16,FALSE)="","",VLOOKUP($B15,INDIRECT("'GRD-"&AG15&"'!$B:$R"),16,FALSE))) | AG15: {=IF(AE15="","",IFERROR(OFFSET($BZ$11,0,MATCH($AE15,$CA15:$FV15,0),),""))} | AH15: {=IF(AE15="","",INDIRECT("'GRD-"&AG15&"'!$L$7"))} | AI15: {=IFERROR(OFFSET($BZ$11,ROW($B15)-11,MATCH(AI$10,$CA15:$FV15,0),),"")} | AJ15: =IF(AI15="","",IF(VLOOKUP($B15,INDIRECT("'GRD-"&AK15&"'!$B:$R"),16,FALSE)="","",VLOOKUP($B15,INDIRECT("'GRD-"&AK15&"'!$B:$R"),16,FALSE))) | AK15: {=IF(AI15="","",IFERROR(OFFSET($BZ$11,0,MATCH($AI15,$CA15:$FV15,0),),""))} | AL15: {=IF(AI15="","",INDIRECT("'GRD-"&AK15&"'!$L$7"))} | AM15: {=IFERROR(OFFSET($BZ$11,ROW($B15)-11,MATCH(AM$10,$CA15:$FV15,0),),"")} | AN15: =IF(AM15="","",IF(VLOOKUP($B15,INDIRECT("'GRD-"&AO15&"'!$B:$R"),16,FALSE)="","",VLOOKUP($B15,INDIRECT("'GRD-"&AO15&"'!$B:$R"),16,FALSE))) | AO15: {=IF(AM15="","",IFERROR(OFFSET($BZ$11,0,MATCH($AM15,$CA15:$FV15,0),),""))} | AP15: {=IF(AM15="","",INDIRECT("'GRD-"&AO15&"'!$L$7"))} | AQ15: {=IFERROR(OFFSET($BZ$11,ROW($B15)-11,MATCH(AQ$10,$CA15:$FV15,0),),"")} | AR15: =IF(AQ15="","",IF(VLOOKUP($B15,INDIRECT("'GRD-"&AS15&"'!$B:$R"),16,FALSE)="","",VLOOKUP($B15,INDIRECT("'GRD-"&AS15&"'!$B:$R"),16,FALSE))) | AS15: {=IF(AQ15="","",IFERROR(OFFSET($BZ$11,0,MATCH($AQ15,$CA15:$FV15,0),),""))} | AT15: {=IF(AQ15="","",INDIRECT("'GRD-"&AS15&"'!$L$7"))} | AU15: {=IFERROR(OFFSET($BZ$11,ROW($B15)-11,MATCH(AU$10,$CA15:$FV15,0),),"")} | AV15: =IF(AU15="","",IF(VLOOKUP($B15,INDIRECT("'GRD-"&AW15&"'!$B:$R"),16,FALSE)="","",VLOOKUP($B15,INDIRECT("'GRD-"&AW15&"'!$B:$R"),16,FALSE))) | AW15: {=IF(AU15="","",IFERROR(OFFSET($BZ$11,0,MATCH($AU15,$CA15:$FV15,0),),""))} | AX15: {=IF(AU15="","",INDIRECT("'GRD-"&AW15&"'!$L$7"))} | AY15: {=IFERROR(OFFSET($BZ$11,ROW($B15)-11,MATCH(AY$10,$CA15:$FV15,0),),"")} | AZ15: =IF(AY15="","",IF(VLOOKUP($B15,INDIRECT("'GRD-"&BA15&"'!$B:$R"),16,FALSE)="","",VLOOKUP($B15,INDIRECT("'GRD-"&BA15&"'!$B:$R"),16,FALSE))) | BA15: {=IF(AY15="","",IFERROR(OFFSET($BZ$11,0,MATCH($AY15,$CA15:$FV15,0),),""))} | BB15: {=IF(AY15="","",INDIRECT("'GRD-"&BA15&"'!$L$7"))} | BC15: {=IFERROR(OFFSET($BZ$11,ROW($B15)-11,MATCH(BC$10,$CA15:$FV15,0),),"")} | BD15: =IF(BC15="","",IF(VLOOKUP($B15,INDIRECT("'GRD-"&BE15&"'!$B:$R"),16,FALSE)="","",VLOOKUP($B15,INDIRECT("'GRD-"&BE15&"'!$B:$R"),16,FALSE))) | BE15: {=IF(BC15="","",IFERROR(OFFSET($BZ$11,0,MATCH($BC15,$CA15:$FV15,0),),""))} | BF15: {=IF(BC15="","",INDIRECT("'GRD-"&BE15&"'!$L$7"))} | CA15: =IFERROR(VLOOKUP($B15,INDIRECT("'GRD-"&CA$11&"'!B:R"),15,FALSE),"") | CB15: =IFERROR(VLOOKUP($B15,INDIRECT("'GRD-"&CB$11&"'!B:R"),15,FALSE),"") | CC15: =IFERROR(VLOOKUP($B15,INDIRECT("'GRD-"&CC$11&"'!B:R"),15,FALSE),"") | CD15: =IFERROR(VLOOKUP($B15,INDIRECT("'GRD-"&CD$11&"'!B:R"),15,FALSE),"") | CE15: =IFERROR(VLOOKUP($B15,INDIRECT("'GRD-"&CE$11&"'!B:R"),15,FALSE),"") | CF15: =IFERROR(VLOOKUP($B15,INDIRECT("'GRD-"&CF$11&"'!B:R"),15,FALSE),"") | CG15: =IFERROR(VLOOKUP($B15,INDIRECT("'GRD-"&CG$11&"'!B:R"),15,FALSE),"") | CH15: =IFERROR(VLOOKUP($B15,INDIRECT("'GRD-"&CH$11&"'!B:R"),15,FALSE),"") | ... FV15: =IFERROR(VLOOKUP($B15,INDIRECT("'GRD-"&FV$11&"'!B:R"),15,FALSE),"")
B16: ... | D16: =IF(K16="","",MAX($CA16:$FV16)) | E16: {=IF($K16="","",OFFSET($A$1,ROW($B16)-1,11+$D16*4,))} | F16: {=IF($K16="","",OFFSET($A$1,ROW($B16)-1,12+$D16*4,))} | G16: {=IF($K16="","",OFFSET($A$1,ROW($B16)-1,13+$D16*4,))} | J16: =IF(I16="A4",H16/8,IF(I16="A3",H16/4,IF(I16="A2",H16/2,IF(I16="A1",H16/1,IF(I16="A0",H16*2,""))))) | K16: {=IFERROR(OFFSET($BZ$11,ROW($B16)-11,MATCH(K$10,$CA16:$FV16,0),),"")} | L16: =IF(K16="","",IF(VLOOKUP($B16,INDIRECT("'GRD-"&M16&"'!$B:$R"),16,FALSE)="","",VLOOKUP($B16,INDIRECT("'GRD-"&M16&"'!$B:$R"),16,FALSE))) | M16: {=IF(K16="","",IFERROR(OFFSET($BZ$11,0,MATCH($K16,$CA16:$FV16,0),),""))} | N16: {=IF(K16="","",INDIRECT("'GRD-"&M16&"'!$L$7"))} | O16: {=IFERROR(OFFSET($BZ$11,ROW($B16)-11,MATCH(O$10,$CA16:$FV16,0),),"")} | P16: =IF(O16="","",IF(VLOOKUP($B16,INDIRECT("'GRD-"&Q16&"'!$B:$R"),16,FALSE)="","",VLOOKUP($B16,INDIRECT("'GRD-"&Q16&"'!$B:$R"),16,FALSE))) | Q16: {=IF(O16="","",IFERROR(OFFSET($BZ$11,0,MATCH($O16,$CA16:$FV16,0),),""))} | R16: {=IF(O16="","",INDIRECT("'GRD-"&Q16&"'!$L$7"))} | S16: {=IFERROR(OFFSET($BZ$11,ROW($B16)-11,MATCH(S$10,$CA16:$FV16,0),),"")} | T16: =IF(S16="","",IF(VLOOKUP($B16,INDIRECT("'GRD-"&U16&"'!$B:$R"),16,FALSE)="","",VLOOKUP($B16,INDIRECT("'GRD-"&U16&"'!$B:$R"),16,FALSE))) | U16: {=IF(S16="","",IFERROR(OFFSET($BZ$11,0,MATCH($S16,$CA16:$FV16,0),),""))} | V16: {=IF(S16="","",INDIRECT("'GRD-"&U16&"'!$L$7"))} | W16: {=IFERROR(OFFSET($BZ$11,ROW($B16)-11,MATCH(W$10,$CA16:$FV16,0),),"")} | X16: =IF(W16="","",IF(VLOOKUP($B16,INDIRECT("'GRD-"&Y16&"'!$B:$R"),16,FALSE)="","",VLOOKUP($B16,INDIRECT("'GRD-"&Y16&"'!$B:$R"),16,FALSE))) | Y16: {=IF(W16="","",IFERROR(OFFSET($BZ$11,0,MATCH($W16,$CA16:$FV16,0),),""))} | Z16: {=IF(W16="","",INDIRECT("'GRD-"&Y16&"'!$L$7"))} | AA16: {=IFERROR(OFFSET($BZ$11,ROW($B16)-11,MATCH(AA$10,$CA16:$FV16,0),),"")} | AB16: =IF(AA16="","",IF(VLOOKUP($B16,INDIRECT("'GRD-"&AC16&"'!$B:$R"),16,FALSE)="","",VLOOKUP($B16,INDIRECT("'GRD-"&AC16&"'!$B:$R"),16,FALSE))) | AC16: {=IF(AA16="","",IFERROR(OFFSET($BZ$11,0,MATCH($AA16,$CA16:$FV16,0),),""))} | AD16: {=IF(AA16="","",INDIRECT("'GRD-"&AC16&"'!$L$7"))} | AE16: {=IFERROR(OFFSET($BZ$11,ROW($B16)-11,MATCH(AE$10,$CA16:$FV16,0),),"")} | AF16: =IF(AE16="","",IF(VLOOKUP($B16,INDIRECT("'GRD-"&AG16&"'!$B:$R"),16,FALSE)="","",VLOOKUP($B16,INDIRECT("'GRD-"&AG16&"'!$B:$R"),16,FALSE))) | AG16: {=IF(AE16="","",IFERROR(OFFSET($BZ$11,0,MATCH($AE16,$CA16:$FV16,0),),""))} | AH16: {=IF(AE16="","",INDIRECT("'GRD-"&AG16&"'!$L$7"))} | AI16: {=IFERROR(OFFSET($BZ$11,ROW($B16)-11,MATCH(AI$10,$CA16:$FV16,0),),"")} | AJ16: =IF(AI16="","",IF(VLOOKUP($B16,INDIRECT("'GRD-"&AK16&"'!$B:$R"),16,FALSE)="","",VLOOKUP($B16,INDIRECT("'GRD-"&AK16&"'!$B:$R"),16,FALSE))) | AK16: {=IF(AI16="","",IFERROR(OFFSET($BZ$11,0,MATCH($AI16,$CA16:$FV16,0),),""))} | AL16: {=IF(AI16="","",INDIRECT("'GRD-"&AK16&"'!$L$7"))} | AM16: {=IFERROR(OFFSET($BZ$11,ROW($B16)-11,MATCH(AM$10,$CA16:$FV16,0),),"")} | AN16: =IF(AM16="","",IF(VLOOKUP($B16,INDIRECT("'GRD-"&AO16&"'!$B:$R"),16,FALSE)="","",VLOOKUP($B16,INDIRECT("'GRD-"&AO16&"'!$B:$R"),16,FALSE))) | AO16: {=IF(AM16="","",IFERROR(OFFSET($BZ$11,0,MATCH($AM16,$CA16:$FV16,0),),""))} | AP16: {=IF(AM16="","",INDIRECT("'GRD-"&AO16&"'!$L$7"))} | AQ16: {=IFERROR(OFFSET($BZ$11,ROW($B16)-11,MATCH(AQ$10,$CA16:$FV16,0),),"")} | AR16: =IF(AQ16="","",IF(VLOOKUP($B16,INDIRECT("'GRD-"&AS16&"'!$B:$R"),16,FALSE)="","",VLOOKUP($B16,INDIRECT("'GRD-"&AS16&"'!$B:$R"),16,FALSE))) | AS16: {=IF(AQ16="","",IFERROR(OFFSET($BZ$11,0,MATCH($AQ16,$CA16:$FV16,0),),""))} | AT16: {=IF(AQ16="","",INDIRECT("'GRD-"&AS16&"'!$L$7"))} | AU16: {=IFERROR(OFFSET($BZ$11,ROW($B16)-11,MATCH(AU$10,$CA16:$FV16,0),),"")} | AV16: =IF(AU16="","",IF(VLOOKUP($B16,INDIRECT("'GRD-"&AW16&"'!$B:$R"),16,FALSE)="","",VLOOKUP($B16,INDIRECT("'GRD-"&AW16&"'!$B:$R"),16,FALSE))) | AW16: {=IF(AU16="","",IFERROR(OFFSET($BZ$11,0,MATCH($AU16,$CA16:$FV16,0),),""))} | AX16: {=IF(AU16="","",INDIRECT("'GRD-"&AW16&"'!$L$7"))} | AY16: {=IFERROR(OFFSET($BZ$11,ROW($B16)-11,MATCH(AY$10,$CA16:$FV16,0),),"")} | AZ16: =IF(AY16="","",IF(VLOOKUP($B16,INDIRECT("'GRD-"&BA16&"'!$B:$R"),16,FALSE)="","",VLOOKUP($B16,INDIRECT("'GRD-"&BA16&"'!$B:$R"),16,FALSE))) | BA16: {=IF(AY16="","",IFERROR(OFFSET($BZ$11,0,MATCH($AY16,$CA16:$FV16,0),),""))} | BB16: {=IF(AY16="","",INDIRECT("'GRD-"&BA16&"'!$L$7"))} | BC16: {=IFERROR(OFFSET($BZ$11,ROW($B16)-11,MATCH(BC$10,$CA16:$FV16,0),),"")} | BD16: =IF(BC16="","",IF(VLOOKUP($B16,INDIRECT("'GRD-"&BE16&"'!$B:$R"),16,FALSE)="","",VLOOKUP($B16,INDIRECT("'GRD-"&BE16&"'!$B:$R"),16,FALSE))) | BE16: {=IF(BC16="","",IFERROR(OFFSET($BZ$11,0,MATCH($BC16,$CA16:$FV16,0),),""))} | BF16: {=IF(BC16="","",INDIRECT("'GRD-"&BE16&"'!$L$7"))} | CA16: =IFERROR(VLOOKUP($B16,INDIRECT("'GRD-"&CA$11&"'!B:R"),15,FALSE),"") | CB16: =IFERROR(VLOOKUP($B16,INDIRECT("'GRD-"&CB$11&"'!B:R"),15,FALSE),"") | CC16: =IFERROR(VLOOKUP($B16,INDIRECT("'GRD-"&CC$11&"'!B:R"),15,FALSE),"") | CD16: =IFERROR(VLOOKUP($B16,INDIRECT("'GRD-"&CD$11&"'!B:R"),15,FALSE),"") | CE16: =IFERROR(VLOOKUP($B16,INDIRECT("'GRD-"&CE$11&"'!B:R"),15,FALSE),"") | CF16: =IFERROR(VLOOKUP($B16,INDIRECT("'GRD-"&CF$11&"'!B:R"),15,FALSE),"") | CG16: =IFERROR(VLOOKUP($B16,INDIRECT("'GRD-"&CG$11&"'!B:R"),15,FALSE),"") | CH16: =IFERROR(VLOOKUP($B16,INDIRECT("'GRD-"&CH$11&"'!B:R"),15,FALSE),"") | ... FV16: =IFERROR(VLOOKUP($B16,INDIRECT("'GRD-"&FV$11&"'!B:R"),15,FALSE),"")
B17: IFS-9999-001-X-DC-00001 | C17: Titulo Primeiro Doc | D17: =IF(K17="","",MAX($CA17:$FV17)) | E17: {=IF($K17="","",OFFSET($A$1,ROW($B17)-1,11+$D17*4,))} | F17: {=IF($K17="","",OFFSET($A$1,ROW($B17)-1,12+$D17*4,))} | G17: {=IF($K17="","",OFFSET($A$1,ROW($B17)-1,13+$D17*4,))} | J17: =IF(I17="A4",H17/8,IF(I17="A3",H17/4,IF(I17="A2",H17/2,IF(I17="A1",H17/1,IF(I17="A0",H17*2,""))))) | K17: {=IFERROR(OFFSET($BZ$11,ROW($B17)-11,MATCH(K$10,$CA17:$FV17,0),),"")} | L17: =IF(K17="","",IF(VLOOKUP($B17,INDIRECT("'GRD-"&M17&"'!$B:$R"),16,FALSE)="","",VLOOKUP($B17,INDIRECT("'GRD-"&M17&"'!$B:$R"),16,FALSE))) | M17: {=IF(K17="","",IFERROR(OFFSET($BZ$11,0,MATCH($K17,$CA17:$FV17,0),),""))} | N17: {=IF(K17="","",INDIRECT("'GRD-"&M17&"'!$L$7"))} | O17: {=IFERROR(OFFSET($BZ$11,ROW($B17)-11,MATCH(O$10,$CA17:$FV17,0),),"")} | P17: =IF(O17="","",IF(VLOOKUP($B17,INDIRECT("'GRD-"&Q17&"'!$B:$R"),16,FALSE)="","",VLOOKUP($B17,INDIRECT("'GRD-"&Q17&"'!$B:$R"),16,FALSE))) | Q17: {=IF(O17="","",IFERROR(OFFSET($BZ$11,0,MATCH($O17,$CA17:$FV17,0),),""))} | R17: {=IF(O17="","",INDIRECT("'GRD-"&Q17&"'!$L$7"))} | S17: {=IFERROR(OFFSET($BZ$11,ROW($B17)-11,MATCH(S$10,$CA17:$FV17,0),),"")} | T17: =IF(S17="","",IF(VLOOKUP($B17,INDIRECT("'GRD-"&U17&"'!$B:$R"),16,FALSE)="","",VLOOKUP($B17,INDIRECT("'GRD-"&U17&"'!$B:$R"),16,FALSE))) | U17: {=IF(S17="","",IFERROR(OFFSET($BZ$11,0,MATCH($S17,$CA17:$FV17,0),),""))} | V17: {=IF(S17="","",INDIRECT("'GRD-"&U17&"'!$L$7"))} | W17: {=IFERROR(OFFSET($BZ$11,ROW($B17)-11,MATCH(W$10,$CA17:$FV17,0),),"")} | X17: =IF(W17="","",IF(VLOOKUP($B17,INDIRECT("'GRD-"&Y17&"'!$B:$R"),16,FALSE)="","",VLOOKUP($B17,INDIRECT("'GRD-"&Y17&"'!$B:$R"),16,FALSE))) | Y17: {=IF(W17="","",IFERROR(OFFSET($BZ$11,0,MATCH($W17,$CA17:$FV17,0),),""))} | Z17: {=IF(W17="","",INDIRECT("'GRD-"&Y17&"'!$L$7"))} | AA17: {=IFERROR(OFFSET($BZ$11,ROW($B17)-11,MATCH(AA$10,$CA17:$FV17,0),),"")} | AB17: =IF(AA17="","",IF(VLOOKUP($B17,INDIRECT("'GRD-"&AC17&"'!$B:$R"),16,FALSE)="","",VLOOKUP($B17,INDIRECT("'GRD-"&AC17&"'!$B:$R"),16,FALSE))) | AC17: {=IF(AA17="","",IFERROR(OFFSET($BZ$11,0,MATCH($AA17,$CA17:$FV17,0),),""))} | AD17: {=IF(AA17="","",INDIRECT("'GRD-"&AC17&"'!$L$7"))} | AE17: {=IFERROR(OFFSET($BZ$11,ROW($B17)-11,MATCH(AE$10,$CA17:$FV17,0),),"")} | AF17: =IF(AE17="","",IF(VLOOKUP($B17,INDIRECT("'GRD-"&AG17&"'!$B:$R"),16,FALSE)="","",VLOOKUP($B17,INDIRECT("'GRD-"&AG17&"'!$B:$R"),16,FALSE))) | AG17: {=IF(AE17="","",IFERROR(OFFSET($BZ$11,0,MATCH($AE17,$CA17:$FV17,0),),""))} | AH17: {=IF(AE17="","",INDIRECT("'GRD-"&AG17&"'!$L$7"))} | AI17: {=IFERROR(OFFSET($BZ$11,ROW($B17)-11,MATCH(AI$10,$CA17:$FV17,0),),"")} | AJ17: =IF(AI17="","",IF(VLOOKUP($B17,INDIRECT("'GRD-"&AK17&"'!$B:$R"),16,FALSE)="","",VLOOKUP($B17,INDIRECT("'GRD-"&AK17&"'!$B:$R"),16,FALSE))) | AK17: {=IF(AI17="","",IFERROR(OFFSET($BZ$11,0,MATCH($AI17,$CA17:$FV17,0),),""))} | AL17: {=IF(AI17="","",INDIRECT("'GRD-"&AK17&"'!$L$7"))} | AM17: {=IFERROR(OFFSET($BZ$11,ROW($B17)-11,MATCH(AM$10,$CA17:$FV17,0),),"")} | AN17: =IF(AM17="","",IF(VLOOKUP($B17,INDIRECT("'GRD-"&AO17&"'!$B:$R"),16,FALSE)="","",VLOOKUP($B17,INDIRECT("'GRD-"&AO17&"'!$B:$R"),16,FALSE))) | AO17: {=IF(AM17="","",IFERROR(OFFSET($BZ$11,0,MATCH($AM17,$CA17:$FV17,0),),""))} | AP17: {=IF(AM17="","",INDIRECT("'GRD-"&AO17&"'!$L$7"))} | AQ17: {=IFERROR(OFFSET($BZ$11,ROW($B17)-11,MATCH(AQ$10,$CA17:$FV17,0),),"")} | AR17: =IF(AQ17="","",IF(VLOOKUP($B17,INDIRECT("'GRD-"&AS17&"'!$B:$R"),16,FALSE)="","",VLOOKUP($B17,INDIRECT("'GRD-"&AS17&"'!$B:$R"),16,FALSE))) | AS17: {=IF(AQ17="","",IFERROR(OFFSET($BZ$11,0,MATCH($AQ17,$CA17:$FV17,0),),""))} | AT17: {=IF(AQ17="","",INDIRECT("'GRD-"&AS17&"'!$L$7"))} | AU17: {=IFERROR(OFFSET($BZ$11,ROW($B17)-11,MATCH(AU$10,$CA17:$FV17,0),),"")} | AV17: =IF(AU17="","",IF(VLOOKUP($B17,INDIRECT("'GRD-"&AW17&"'!$B:$R"),16,FALSE)="","",VLOOKUP($B17,INDIRECT("'GRD-"&AW17&"'!$B:$R"),16,FALSE))) | AW17: {=IF(AU17="","",IFERROR(OFFSET($BZ$11,0,MATCH($AU17,$CA17:$FV17,0),),""))} | AX17: {=IF(AU17="","",INDIRECT("'GRD-"&AW17&"'!$L$7"))} | AY17: {=IFERROR(OFFSET($BZ$11,ROW($B17)-11,MATCH(AY$10,$CA17:$FV17,0),),"")} | AZ17: =IF(AY17="","",IF(VLOOKUP($B17,INDIRECT("'GRD-"&BA17&"'!$B:$R"),16,FALSE)="","",VLOOKUP($B17,INDIRECT("'GRD-"&BA17&"'!$B:$R"),16,FALSE))) | BA17: {=IF(AY17="","",IFERROR(OFFSET($BZ$11,0,MATCH($AY17,$CA17:$FV17,0),),""))} | BB17: {=IF(AY17="","",INDIRECT("'GRD-"&BA17&"'!$L$7"))} | BC17: {=IFERROR(OFFSET($BZ$11,ROW($B17)-11,MATCH(BC$10,$CA17:$FV17,0),),"")} | BD17: =IF(BC17="","",IF(VLOOKUP($B17,INDIRECT("'GRD-"&BE17&"'!$B:$R"),16,FALSE)="","",VLOOKUP($B17,INDIRECT("'GRD-"&BE17&"'!$B:$R"),16,FALSE))) | BE17: {=IF(BC17="","",IFERROR(OFFSET($BZ$11,0,MATCH($BC17,$CA17:$FV17,0),),""))} | BF17: {=IF(BC17="","",INDIRECT("'GRD-"&BE17&"'!$L$7"))} | CA17: =IFERROR(VLOOKUP($B17,INDIRECT("'GRD-"&CA$11&"'!B:R"),15,FALSE),"") | CB17: =IFERROR(VLOOKUP($B17,INDIRECT("'GRD-"&CB$11&"'!B:R"),15,FALSE),"") | CC17: =IFERROR(VLOOKUP($B17,INDIRECT("'GRD-"&CC$11&"'!B:R"),15,FALSE),"") | CD17: =IFERROR(VLOOKUP($B17,INDIRECT("'GRD-"&CD$11&"'!B:R"),15,FALSE),"") | CE17: =IFERROR(VLOOKUP($B17,INDIRECT("'GRD-"&CE$11&"'!B:R"),15,FALSE),"") | CF17: =IFERROR(VLOOKUP($B17,INDIRECT("'GRD-"&CF$11&"'!B:R"),15,FALSE),"") | CG17: =IFERROR(VLOOKUP($B17,INDIRECT("'GRD-"&CG$11&"'!B:R"),15,FALSE),"") | CH17: =IFERROR(VLOOKUP($B17,INDIRECT("'GRD-"&CH$11&"'!B:R"),15,FALSE),"") | ... FV17: =IFERROR(VLOOKUP($B17,INDIRECT("'GRD-"&FV$11&"'!B:R"),15,FALSE),"")
B18: IFS-9999-001-X-DC-00002 | C18: Titulo Segundo Doc R0 | D18: =IF(K18="","",MAX($CA18:$FV18)) | E18: {=IF($K18="","",OFFSET($A$1,ROW($B18)-1,11+$D18*4,))} | F18: {=IF($K18="","",OFFSET($A$1,ROW($B18)-1,12+$D18*4,))} | G18: {=IF($K18="","",OFFSET($A$1,ROW($B18)-1,13+$D18*4,))} | J18: =IF(I18="A4",H18/8,IF(I18="A3",H18/4,IF(I18="A2",H18/2,IF(I18="A1",H18/1,IF(I18="A0",H18*2,""))))) | K18: {=IFERROR(OFFSET($BZ$11,ROW($B18)-11,MATCH(K$10,$CA18:$FV18,0),),"")} | L18: =IF(K18="","",IF(VLOOKUP($B18,INDIRECT("'GRD-"&M18&"'!$B:$R"),16,FALSE)="","",VLOOKUP($B18,INDIRECT("'GRD-"&M18&"'!$B:$R"),16,FALSE))) | M18: {=IF(K18="","",IFERROR(OFFSET($BZ$11,0,MATCH($K18,$CA18:$FV18,0),),""))} | N18: {=IF(K18="","",INDIRECT("'GRD-"&M18&"'!$L$7"))} | O18: {=IFERROR(OFFSET($BZ$11,ROW($B18)-11,MATCH(O$10,$CA18:$FV18,0),),"")} | P18: =IF(O18="","",IF(VLOOKUP($B18,INDIRECT("'GRD-"&Q18&"'!$B:$R"),16,FALSE)="","",VLOOKUP($B18,INDIRECT("'GRD-"&Q18&"'!$B:$R"),16,FALSE))) | Q18: {=IF(O18="","",IFERROR(OFFSET($BZ$11,0,MATCH($O18,$CA18:$FV18,0),),""))} | R18: {=IF(O18="","",INDIRECT("'GRD-"&Q18&"'!$L$7"))} | S18: {=IFERROR(OFFSET($BZ$11,ROW($B18)-11,MATCH(S$10,$CA18:$FV18,0),),"")} | T18: =IF(S18="","",IF(VLOOKUP($B18,INDIRECT("'GRD-"&U18&"'!$B:$R"),16,FALSE)="","",VLOOKUP($B18,INDIRECT("'GRD-"&U18&"'!$B:$R"),16,FALSE))) | U18: {=IF(S18="","",IFERROR(OFFSET($BZ$11,0,MATCH($S18,$CA18:$FV18,0),),""))} | V18: {=IF(S18="","",INDIRECT("'GRD-"&U18&"'!$L$7"))} | W18: {=IFERROR(OFFSET($BZ$11,ROW($B18)-11,MATCH(W$10,$CA18:$FV18,0),),"")} | X18: =IF(W18="","",IF(VLOOKUP($B18,INDIRECT("'GRD-"&Y18&"'!$B:$R"),16,FALSE)="","",VLOOKUP($B18,INDIRECT("'GRD-"&Y18&"'!$B:$R"),16,FALSE))) | Y18: {=IF(W18="","",IFERROR(OFFSET($BZ$11,0,MATCH($W18,$CA18:$FV18,0),),""))} | Z18: {=IF(W18="","",INDIRECT("'GRD-"&Y18&"'!$L$7"))} | AA18: {=IFERROR(OFFSET($BZ$11,ROW($B18)-11,MATCH(AA$10,$CA18:$FV18,0),),"")} | AB18: =IF(AA18="","",IF(VLOOKUP($B18,INDIRECT("'GRD-"&AC18&"'!$B:$R"),16,FALSE)="","",VLOOKUP($B18,INDIRECT("'GRD-"&AC18&"'!$B:$R"),16,FALSE))) | AC18: {=IF(AA18="","",IFERROR(OFFSET($BZ$11,0,MATCH($AA18,$CA18:$FV18,0),),""))} | AD18: {=IF(AA18="","",INDIRECT("'GRD-"&AC18&"'!$L$7"))} | AE18: {=IFERROR(OFFSET($BZ$11,ROW($B18)-11,MATCH(AE$10,$CA18:$FV18,0),),"")} | AF18: =IF(AE18="","",IF(VLOOKUP($B18,INDIRECT("'GRD-"&AG18&"'!$B:$R"),16,FALSE)="","",VLOOKUP($B18,INDIRECT("'GRD-"&AG18&"'!$B:$R"),16,FALSE))) | AG18: {=IF(AE18="","",IFERROR(OFFSET($BZ$11,0,MATCH($AE18,$CA18:$FV18,0),),""))} | AH18: {=IF(AE18="","",INDIRECT("'GRD-"&AG18&"'!$L$7"))} | AI18: {=IFERROR(OFFSET($BZ$11,ROW($B18)-11,MATCH(AI$10,$CA18:$FV18,0),),"")} | AJ18: =IF(AI18="","",IF(VLOOKUP($B18,INDIRECT("'GRD-"&AK18&"'!$B:$R"),16,FALSE)="","",VLOOKUP($B18,INDIRECT("'GRD-"&AK18&"'!$B:$R"),16,FALSE))) | AK18: {=IF(AI18="","",IFERROR(OFFSET($BZ$11,0,MATCH($AI18,$CA18:$FV18,0),),""))} | AL18: {=IF(AI18="","",INDIRECT("'GRD-"&AK18&"'!$L$7"))} | AM18: {=IFERROR(OFFSET($BZ$11,ROW($B18)-11,MATCH(AM$10,$CA18:$FV18,0),),"")} | AN18: =IF(AM18="","",IF(VLOOKUP($B18,INDIRECT("'GRD-"&AO18&"'!$B:$R"),16,FALSE)="","",VLOOKUP($B18,INDIRECT("'GRD-"&AO18&"'!$B:$R"),16,FALSE))) | AO18: {=IF(AM18="","",IFERROR(OFFSET($BZ$11,0,MATCH($AM18,$CA18:$FV18,0),),""))} | AP18: {=IF(AM18="","",INDIRECT("'GRD-"&AO18&"'!$L$7"))} | AQ18: {=IFERROR(OFFSET($BZ$11,ROW($B18)-11,MATCH(AQ$10,$CA18:$FV18,0),),"")} | AR18: =IF(AQ18="","",IF(VLOOKUP($B18,INDIRECT("'GRD-"&AS18&"'!$B:$R"),16,FALSE)="","",VLOOKUP($B18,INDIRECT("'GRD-"&AS18&"'!$B:$R"),16,FALSE))) | AS18: {=IF(AQ18="","",IFERROR(OFFSET($BZ$11,0,MATCH($AQ18,$CA18:$FV18,0),),""))} | AT18: {=IF(AQ18="","",INDIRECT("'GRD-"&AS18&"'!$L$7"))} | AU18: {=IFERROR(OFFSET($BZ$11,ROW($B18)-11,MATCH(AU$10,$CA18:$FV18,0),),"")} | AV18: =IF(AU18="","",IF(VLOOKUP($B18,INDIRECT("'GRD-"&AW18&"'!$B:$R"),16,FALSE)="","",VLOOKUP($B18,INDIRECT("'GRD-"&AW18&"'!$B:$R"),16,FALSE))) | AW18: {=IF(AU18="","",IFERROR(OFFSET($BZ$11,0,MATCH($AU18,$CA18:$FV18,0),),""))} | AX18: {=IF(AU18="","",INDIRECT("'GRD-"&AW18&"'!$L$7"))} | AY18: {=IFERROR(OFFSET($BZ$11,ROW($B18)-11,MATCH(AY$10,$CA18:$FV18,0),),"")} | AZ18: =IF(AY18="","",IF(VLOOKUP($B18,INDIRECT("'GRD-"&BA18&"'!$B:$R"),16,FALSE)="","",VLOOKUP($B18,INDIRECT("'GRD-"&BA18&"'!$B:$R"),16,FALSE))) | BA18: {=IF(AY18="","",IFERROR(OFFSET($BZ$11,0,MATCH($AY18,$CA18:$FV18,0),),""))} | BB18: {=IF(AY18="","",INDIRECT("'GRD-"&BA18&"'!$L$7"))} | BC18: {=IFERROR(OFFSET($BZ$11,ROW($B18)-11,MATCH(BC$10,$CA18:$FV18,0),),"")} | BD18: =IF(BC18="","",IF(VLOOKUP($B18,INDIRECT("'GRD-"&BE18&"'!$B:$R"),16,FALSE)="","",VLOOKUP($B18,INDIRECT("'GRD-"&BE18&"'!$B:$R"),16,FALSE))) | BE18: {=IF(BC18="","",IFERROR(OFFSET($BZ$11,0,MATCH($BC18,$CA18:$FV18,0),),""))} | BF18: {=IF(BC18="","",INDIRECT("'GRD-"&BE18&"'!$L$7"))} | CA18: =IFERROR(VLOOKUP($B18,INDIRECT("'GRD-"&CA$11&"'!B:R"),15,FALSE),"") | CB18: =IFERROR(VLOOKUP($B18,INDIRECT("'GRD-"&CB$11&"'!B:R"),15,FALSE),"") | CC18: =IFERROR(VLOOKUP($B18,INDIRECT("'GRD-"&CC$11&"'!B:R"),15,FALSE),"") | CD18: =IFERROR(VLOOKUP($B18,INDIRECT("'GRD-"&CD$11&"'!B:R"),15,FALSE),"") | CE18: =IFERROR(VLOOKUP($B18,INDIRECT("'GRD-"&CE$11&"'!B:R"),15,FALSE),"") | CF18: =IFERROR(VLOOKUP($B18,INDIRECT("'GRD-"&CF$11&"'!B:R"),15,FALSE),"") | CG18: =IFERROR(VLOOKUP($B18,INDIRECT("'GRD-"&CG$11&"'!B:R"),15,FALSE),"") | CH18: =IFERROR(VLOOKUP($B18,INDIRECT("'GRD-"&CH$11&"'!B:R"),15,FALSE),"") | ... FV18: =IFERROR(VLOOKUP($B18,INDIRECT("'GRD-"&FV$11&"'!B:R"),15,FALSE),"")
D19: =IF(K19="","",MAX($CA19:$FV19)) | E19: {=IF($K19="","",OFFSET($A$1,ROW($B19)-1,11+$D19*4,))} | F19: {=IF($K19="","",OFFSET($A$1,ROW($B19)-1,12+$D19*4,))} | G19: {=IF($K19="","",OFFSET($A$1,ROW($B19)-1,13+$D19*4,))} | J19: =IF(I19="A4",H19/8,IF(I19="A3",H19/4,IF(I19="A2",H19/2,IF(I19="A1",H19/1,IF(I19="A0",H19*2,""))))) | K19: {=IFERROR(OFFSET($BZ$11,ROW($B19)-11,MATCH(K$10,$CA19:$FV19,0),),"")} | L19: =IF(K19="","",IF(VLOOKUP($B19,INDIRECT("'GRD-"&M19&"'!$B:$R"),16,FALSE)="","",VLOOKUP($B19,INDIRECT("'GRD-"&M19&"'!$B:$R"),16,FALSE))) | M19: {=IF(K19="","",IFERROR(OFFSET($BZ$11,0,MATCH($K19,$CA19:$FV19,0),),""))} | N19: {=IF(K19="","",INDIRECT("'GRD-"&M19&"'!$L$7"))} | O19: {=IFERROR(OFFSET($BZ$11,ROW($B19)-11,MATCH(O$10,$CA19:$FV19,0),),"")} | P19: =IF(O19="","",IF(VLOOKUP($B19,INDIRECT("'GRD-"&Q19&"'!$B:$R"),16,FALSE)="","",VLOOKUP($B19,INDIRECT("'GRD-"&Q19&"'!$B:$R"),16,FALSE))) | Q19: {=IF(O19="","",IFERROR(OFFSET($BZ$11,0,MATCH($O19,$CA19:$FV19,0),),""))} | R19: {=IF(O19="","",INDIRECT("'GRD-"&Q19&"'!$L$7"))} | S19: {=IFERROR(OFFSET($BZ$11,ROW($B19)-11,MATCH(S$10,$CA19:$FV19,0),),"")} | T19: =IF(S19="","",IF(VLOOKUP($B19,INDIRECT("'GRD-"&U19&"'!$B:$R"),16,FALSE)="","",VLOOKUP($B19,INDIRECT("'GRD-"&U19&"'!$B:$R"),16,FALSE))) | U19: {=IF(S19="","",IFERROR(OFFSET($BZ$11,0,MATCH($S19,$CA19:$FV19,0),),""))} | V19: {=IF(S19="","",INDIRECT("'GRD-"&U19&"'!$L$7"))} | W19: {=IFERROR(OFFSET($BZ$11,ROW($B19)-11,MATCH(W$10,$CA19:$FV19,0),),"")} | X19: =IF(W19="","",IF(VLOOKUP($B19,INDIRECT("'GRD-"&Y19&"'!$B:$R"),16,FALSE)="","",VLOOKUP($B19,INDIRECT("'GRD-"&Y19&"'!$B:$R"),16,FALSE))) | Y19: {=IF(W19="","",IFERROR(OFFSET($BZ$11,0,MATCH($W19,$CA19:$FV19,0),),""))} | Z19: {=IF(W19="","",INDIRECT("'GRD-"&Y19&"'!$L$7"))} | AA19: {=IFERROR(OFFSET($BZ$11,ROW($B19)-11,MATCH(AA$10,$CA19:$FV19,0),),"")} | AB19: =IF(AA19="","",IF(VLOOKUP($B19,INDIRECT("'GRD-"&AC19&"'!$B:$R"),16,FALSE)="","",VLOOKUP($B19,INDIRECT("'GRD-"&AC19&"'!$B:$R"),16,FALSE))) | AC19: {=IF(AA19="","",IFERROR(OFFSET($BZ$11,0,MATCH($AA19,$CA19:$FV19,0),),""))} | AD19: {=IF(AA19="","",INDIRECT("'GRD-"&AC19&"'!$L$7"))} | AE19: {=IFERROR(OFFSET($BZ$11,ROW($B19)-11,MATCH(AE$10,$CA19:$FV19,0),),"")} | AF19: =IF(AE19="","",IF(VLOOKUP($B19,INDIRECT("'GRD-"&AG19&"'!$B:$R"),16,FALSE)="","",VLOOKUP($B19,INDIRECT("'GRD-"&AG19&"'!$B:$R"),16,FALSE))) | AG19: {=IF(AE19="","",IFERROR(OFFSET($BZ$11,0,MATCH($AE19,$CA19:$FV19,0),),""))} | AH19: {=IF(AE19="","",INDIRECT("'GRD-"&AG19&"'!$L$7"))} | AI19: {=IFERROR(OFFSET($BZ$11,ROW($B19)-11,MATCH(AI$10,$CA19:$FV19,0),),"")} | AJ19: =IF(AI19="","",IF(VLOOKUP($B19,INDIRECT("'GRD-"&AK19&"'!$B:$R"),16,FALSE)="","",VLOOKUP($B19,INDIRECT("'GRD-"&AK19&"'!$B:$R"),16,FALSE))) | AK19: {=IF(AI19="","",IFERROR(OFFSET($BZ$11,0,MATCH($AI19,$CA19:$FV19,0),),""))} | AL19: {=IF(AI19="","",INDIRECT("'GRD-"&AK19&"'!$L$7"))} | AM19: {=IFERROR(OFFSET($BZ$11,ROW($B19)-11,MATCH(AM$10,$CA19:$FV19,0),),"")} | AN19: =IF(AM19="","",IF(VLOOKUP($B19,INDIRECT("'GRD-"&AO19&"'!$B:$R"),16,FALSE)="","",VLOOKUP($B19,INDIRECT("'GRD-"&AO19&"'!$B:$R"),16,FALSE))) | AO19: {=IF(AM19="","",IFERROR(OFFSET($BZ$11,0,MATCH($AM19,$CA19:$FV19,0),),""))} | AP19: {=IF(AM19="","",INDIRECT("'GRD-"&AO19&"'!$L$7"))} | AQ19: {=IFERROR(OFFSET($BZ$11,ROW($B19)-11,MATCH(AQ$10,$CA19:$FV19,0),),"")} | AR19: =IF(AQ19="","",IF(VLOOKUP($B19,INDIRECT("'GRD-"&AS19&"'!$B:$R"),16,FALSE)="","",VLOOKUP($B19,INDIRECT("'GRD-"&AS19&"'!$B:$R"),16,FALSE))) | AS19: {=IF(AQ19="","",IFERROR(OFFSET($BZ$11,0,MATCH($AQ19,$CA19:$FV19,0),),""))} | AT19: {=IF(AQ19="","",INDIRECT("'GRD-"&AS19&"'!$L$7"))} | AU19: {=IFERROR(OFFSET($BZ$11,ROW($B19)-11,MATCH(AU$10,$CA19:$FV19,0),),"")} | AV19: =IF(AU19="","",IF(VLOOKUP($B19,INDIRECT("'GRD-"&AW19&"'!$B:$R"),16,FALSE)="","",VLOOKUP($B19,INDIRECT("'GRD-"&AW19&"'!$B:$R"),16,FALSE))) | AW19: {=IF(AU19="","",IFERROR(OFFSET($BZ$11,0,MATCH($AU19,$CA19:$FV19,0),),""))} | AX19: {=IF(AU19="","",INDIRECT("'GRD-"&AW19&"'!$L$7"))} | AY19: {=IFERROR(OFFSET($BZ$11,ROW($B19)-11,MATCH(AY$10,$CA19:$FV19,0),),"")} | AZ19: =IF(AY19="","",IF(VLOOKUP($B19,INDIRECT("'GRD-"&BA19&"'!$B:$R"),16,FALSE)="","",VLOOKUP($B19,INDIRECT("'GRD-"&BA19&"'!$B:$R"),16,FALSE))) | BA19: {=IF(AY19="","",IFERROR(OFFSET($BZ$11,0,MATCH($AY19,$CA19:$FV19,0),),""))} | BB19: {=IF(AY19="","",INDIRECT("'GRD-"&BA19&"'!$L$7"))} | BC19: {=IFERROR(OFFSET($BZ$11,ROW($B19)-11,MATCH(BC$10,$CA19:$FV19,0),),"")} | BD19: =IF(BC19="","",IF(VLOOKUP($B19,INDIRECT("'GRD-"&BE19&"'!$B:$R"),16,FALSE)="","",VLOOKUP($B19,INDIRECT("'GRD-"&BE19&"'!$B:$R"),16,FALSE))) | BE19: {=IF(BC19="","",IFERROR(OFFSET($BZ$11,0,MATCH($BC19,$CA19:$FV19,0),),""))} | BF19: {=IF(BC19="","",INDIRECT("'GRD-"&BE19&"'!$L$7"))} | CA19: =IFERROR(VLOOKUP($B19,INDIRECT("'GRD-"&CA$11&"'!B:R"),15,FALSE),"") | CB19: =IFERROR(VLOOKUP($B19,INDIRECT("'GRD-"&CB$11&"'!B:R"),15,FALSE),"") | CC19: =IFERROR(VLOOKUP($B19,INDIRECT("'GRD-"&CC$11&"'!B:R"),15,FALSE),"") | CD19: =IFERROR(VLOOKUP($B19,INDIRECT("'GRD-"&CD$11&"'!B:R"),15,FALSE),"") | CE19: =IFERROR(VLOOKUP($B19,INDIRECT("'GRD-"&CE$11&"'!B:R"),15,FALSE),"") | CF19: =IFERROR(VLOOKUP($B19,INDIRECT("'GRD-"&CF$11&"'!B:R"),15,FALSE),"") | CG19: =IFERROR(VLOOKUP($B19,INDIRECT("'GRD-"&CG$11&"'!B:R"),15,FALSE),"") | CH19: =IFERROR(VLOOKUP($B19,INDIRECT("'GRD-"&CH$11&"'!B:R"),15,FALSE),"") | ... FV19: =IFERROR(VLOOKUP($B19,INDIRECT("'GRD-"&FV$11&"'!B:R"),15,FALSE),"")
D20: =IF(K20="","",MAX($CA20:$FV20)) | E20: {=IF($K20="","",OFFSET($A$1,ROW($B20)-1,11+$D20*4,))} | F20: {=IF($K20="","",OFFSET($A$1,ROW($B20)-1,12+$D20*4,))} | G20: {=IF($K20="","",OFFSET($A$1,ROW($B20)-1,13+$D20*4,))} | J20: =IF(I20="A4",H20/8,IF(I20="A3",H20/4,IF(I20="A2",H20/2,IF(I20="A1",H20/1,IF(I20="A0",H20*2,""))))) | K20: {=IFERROR(OFFSET($BZ$11,ROW($B20)-11,MATCH(K$10,$CA20:$FV20,0),),"")} | L20: =IF(K20="","",IF(VLOOKUP($B20,INDIRECT("'GRD-"&M20&"'!$B:$R"),16,FALSE)="","",VLOOKUP($B20,INDIRECT("'GRD-"&M20&"'!$B:$R"),16,FALSE))) | M20: {=IF(K20="","",IFERROR(OFFSET($BZ$11,0,MATCH($K20,$CA20:$FV20,0),),""))} | N20: {=IF(K20="","",INDIRECT("'GRD-"&M20&"'!$L$7"))} | O20: {=IFERROR(OFFSET($BZ$11,ROW($B20)-11,MATCH(O$10,$CA20:$FV20,0),),"")} | P20: =IF(O20="","",IF(VLOOKUP($B20,INDIRECT("'GRD-"&Q20&"'!$B:$R"),16,FALSE)="","",VLOOKUP($B20,INDIRECT("'GRD-"&Q20&"'!$B:$R"),16,FALSE))) | Q20: {=IF(O20="","",IFERROR(OFFSET($BZ$11,0,MATCH($O20,$CA20:$FV20,0),),""))} | R20: {=IF(O20="","",INDIRECT("'GRD-"&Q20&"'!$L$7"))} | S20: {=IFERROR(OFFSET($BZ$11,ROW($B20)-11,MATCH(S$10,$CA20:$FV20,0),),"")} | T20: =IF(S20="","",IF(VLOOKUP($B20,INDIRECT("'GRD-"&U20&"'!$B:$R"),16,FALSE)="","",VLOOKUP($B20,INDIRECT("'GRD-"&U20&"'!$B:$R"),16,FALSE))) | U20: {=IF(S20="","",IFERROR(OFFSET($BZ$11,0,MATCH($S20,$CA20:$FV20,0),),""))} | V20: {=IF(S20="","",INDIRECT("'GRD-"&U20&"'!$L$7"))} | W20: {=IFERROR(OFFSET($BZ$11,ROW($B20)-11,MATCH(W$10,$CA20:$FV20,0),),"")} | X20: =IF(W20="","",IF(VLOOKUP($B20,INDIRECT("'GRD-"&Y20&"'!$B:$R"),16,FALSE)="","",VLOOKUP($B20,INDIRECT("'GRD-"&Y20&"'!$B:$R"),16,FALSE))) | Y20: {=IF(W20="","",IFERROR(OFFSET($BZ$11,0,MATCH($W20,$CA20:$FV20,0),),""))} | Z20: {=IF(W20="","",INDIRECT("'GRD-"&Y20&"'!$L$7"))} | AA20: {=IFERROR(OFFSET($BZ$11,ROW($B20)-11,MATCH(AA$10,$CA20:$FV20,0),),"")} | AB20: =IF(AA20="","",IF(VLOOKUP($B20,INDIRECT("'GRD-"&AC20&"'!$B:$R"),16,FALSE)="","",VLOOKUP($B20,INDIRECT("'GRD-"&AC20&"'!$B:$R"),16,FALSE))) | AC20: {=IF(AA20="","",IFERROR(OFFSET($BZ$11,0,MATCH($AA20,$CA20:$FV20,0),),""))} | AD20: {=IF(AA20="","",INDIRECT("'GRD-"&AC20&"'!$L$7"))} | AE20: {=IFERROR(OFFSET($BZ$11,ROW($B20)-11,MATCH(AE$10,$CA20:$FV20,0),),"")} | AF20: =IF(AE20="","",IF(VLOOKUP($B20,INDIRECT("'GRD-"&AG20&"'!$B:$R"),16,FALSE)="","",VLOOKUP($B20,INDIRECT("'GRD-"&AG20&"'!$B:$R"),16,FALSE))) | AG20: {=IF(AE20="","",IFERROR(OFFSET($BZ$11,0,MATCH($AE20,$CA20:$FV20,0),),""))} | AH20: {=IF(AE20="","",INDIRECT("'GRD-"&AG20&"'!$L$7"))} | AI20: {=IFERROR(OFFSET($BZ$11,ROW($B20)-11,MATCH(AI$10,$CA20:$FV20,0),),"")} | AJ20: =IF(AI20="","",IF(VLOOKUP($B20,INDIRECT("'GRD-"&AK20&"'!$B:$R"),16,FALSE)="","",VLOOKUP($B20,INDIRECT("'GRD-"&AK20&"'!$B:$R"),16,FALSE))) | AK20: {=IF(AI20="","",IFERROR(OFFSET($BZ$11,0,MATCH($AI20,$CA20:$FV20,0),),""))} | AL20: {=IF(AI20="","",INDIRECT("'GRD-"&AK20&"'!$L$7"))} | AM20: {=IFERROR(OFFSET($BZ$11,ROW($B20)-11,MATCH(AM$10,$CA20:$FV20,0),),"")} | AN20: =IF(AM20="","",IF(VLOOKUP($B20,INDIRECT("'GRD-"&AO20&"'!$B:$R"),16,FALSE)="","",VLOOKUP($B20,INDIRECT("'GRD-"&AO20&"'!$B:$R"),16,FALSE))) | AO20: {=IF(AM20="","",IFERROR(OFFSET($BZ$11,0,MATCH($AM20,$CA20:$FV20,0),),""))} | AP20: {=IF(AM20="","",INDIRECT("'GRD-"&AO20&"'!$L$7"))} | AQ20: {=IFERROR(OFFSET($BZ$11,ROW($B20)-11,MATCH(AQ$10,$CA20:$FV20,0),),"")} | AR20: =IF(AQ20="","",IF(VLOOKUP($B20,INDIRECT("'GRD-"&AS20&"'!$B:$R"),16,FALSE)="","",VLOOKUP($B20,INDIRECT("'GRD-"&AS20&"'!$B:$R"),16,FALSE))) | AS20: {=IF(AQ20="","",IFERROR(OFFSET($BZ$11,0,MATCH($AQ20,$CA20:$FV20,0),),""))} | AT20: {=IF(AQ20="","",INDIRECT("'GRD-"&AS20&"'!$L$7"))} | AU20: {=IFERROR(OFFSET($BZ$11,ROW($B20)-11,MATCH(AU$10,$CA20:$FV20,0),),"")} | AV20: =IF(AU20="","",IF(VLOOKUP($B20,INDIRECT("'GRD-"&AW20&"'!$B:$R"),16,FALSE)="","",VLOOKUP($B20,INDIRECT("'GRD-"&AW20&"'!$B:$R"),16,FALSE))) | AW20: {=IF(AU20="","",IFERROR(OFFSET($BZ$11,0,MATCH($AU20,$CA20:$FV20,0),),""))} | AX20: {=IF(AU20="","",INDIRECT("'GRD-"&AW20&"'!$L$7"))} | AY20: {=IFERROR(OFFSET($BZ$11,ROW($B20)-11,MATCH(AY$10,$CA20:$FV20,0),),"")} | AZ20: =IF(AY20="","",IF(VLOOKUP($B20,INDIRECT("'GRD-"&BA20&"'!$B:$R"),16,FALSE)="","",VLOOKUP($B20,INDIRECT("'GRD-"&BA20&"'!$B:$R"),16,FALSE))) | BA20: {=IF(AY20="","",IFERROR(OFFSET($BZ$11,0,MATCH($AY20,$CA20:$FV20,0),),""))} | BB20: {=IF(AY20="","",INDIRECT("'GRD-"&BA20&"'!$L$7"))} | BC20: {=IFERROR(OFFSET($BZ$11,ROW($B20)-11,MATCH(BC$10,$CA20:$FV20,0),),"")} | BD20: =IF(BC20="","",IF(VLOOKUP($B20,INDIRECT("'GRD-"&BE20&"'!$B:$R"),16,FALSE)="","",VLOOKUP($B20,INDIRECT("'GRD-"&BE20&"'!$B:$R"),16,FALSE))) | BE20: {=IF(BC20="","",IFERROR(OFFSET($BZ$11,0,MATCH($BC20,$CA20:$FV20,0),),""))} | BF20: {=IF(BC20="","",INDIRECT("'GRD-"&BE20&"'!$L$7"))} | CA20: =IFERROR(VLOOKUP($B20,INDIRECT("'GRD-"&CA$11&"'!B:R"),15,FALSE),"") | CB20: =IFERROR(VLOOKUP($B20,INDIRECT("'GRD-"&CB$11&"'!B:R"),15,FALSE),"") | CC20: =IFERROR(VLOOKUP($B20,INDIRECT("'GRD-"&CC$11&"'!B:R"),15,FALSE),"") | CD20: =IFERROR(VLOOKUP($B20,INDIRECT("'GRD-"&CD$11&"'!B:R"),15,FALSE),"") | CE20: =IFERROR(VLOOKUP($B20,INDIRECT("'GRD-"&CE$11&"'!B:R"),15,FALSE),"") | CF20: =IFERROR(VLOOKUP($B20,INDIRECT("'GRD-"&CF$11&"'!B:R"),15,FALSE),"") | CG20: =IFERROR(VLOOKUP($B20,INDIRECT("'GRD-"&CG$11&"'!B:R"),15,FALSE),"") | CH20: =IFERROR(VLOOKUP($B20,INDIRECT("'GRD-"&CH$11&"'!B:R"),15,FALSE),"") | ... FV20: =IFERROR(VLOOKUP($B20,INDIRECT("'GRD-"&FV$11&"'!B:R"),15,FALSE),"")
D21: =IF(K21="","",MAX($CA21:$FV21)) | E21: {=IF($K21="","",OFFSET($A$1,ROW($B21)-1,11+$D21*4,))} | F21: {=IF($K21="","",OFFSET($A$1,ROW($B21)-1,12+$D21*4,))} | G21: {=IF($K21="","",OFFSET($A$1,ROW($B21)-1,13+$D21*4,))} | J21: =IF(I21="A4",H21/8,IF(I21="A3",H21/4,IF(I21="A2",H21/2,IF(I21="A1",H21/1,IF(I21="A0",H21*2,""))))) | K21: {=IFERROR(OFFSET($BZ$11,ROW($B21)-11,MATCH(K$10,$CA21:$FV21,0),),"")} | L21: =IF(K21="","",IF(VLOOKUP($B21,INDIRECT("'GRD-"&M21&"'!$B:$R"),16,FALSE)="","",VLOOKUP($B21,INDIRECT("'GRD-"&M21&"'!$B:$R"),16,FALSE))) | M21: {=IF(K21="","",IFERROR(OFFSET($BZ$11,0,MATCH($K21,$CA21:$FV21,0),),""))} | N21: {=IF(K21="","",INDIRECT("'GRD-"&M21&"'!$L$7"))} | O21: {=IFERROR(OFFSET($BZ$11,ROW($B21)-11,MATCH(O$10,$CA21:$FV21,0),),"")} | P21: =IF(O21="","",IF(VLOOKUP($B21,INDIRECT("'GRD-"&Q21&"'!$B:$R"),16,FALSE)="","",VLOOKUP($B21,INDIRECT("'GRD-"&Q21&"'!$B:$R"),16,FALSE))) | Q21: {=IF(O21="","",IFERROR(OFFSET($BZ$11,0,MATCH($O21,$CA21:$FV21,0),),""))} | R21: {=IF(O21="","",INDIRECT("'GRD-"&Q21&"'!$L$7"))} | S21: {=IFERROR(OFFSET($BZ$11,ROW($B21)-11,MATCH(S$10,$CA21:$FV21,0),),"")} | T21: =IF(S21="","",IF(VLOOKUP($B21,INDIRECT("'GRD-"&U21&"'!$B:$R"),16,FALSE)="","",VLOOKUP($B21,INDIRECT("'GRD-"&U21&"'!$B:$R"),16,FALSE))) | U21: {=IF(S21="","",IFERROR(OFFSET($BZ$11,0,MATCH($S21,$CA21:$FV21,0),),""))} | V21: {=IF(S21="","",INDIRECT("'GRD-"&U21&"'!$L$7"))} | W21: {=IFERROR(OFFSET($BZ$11,ROW($B21)-11,MATCH(W$10,$CA21:$FV21,0),),"")} | X21: =IF(W21="","",IF(VLOOKUP($B21,INDIRECT("'GRD-"&Y21&"'!$B:$R"),16,FALSE)="","",VLOOKUP($B21,INDIRECT("'GRD-"&Y21&"'!$B:$R"),16,FALSE))) | Y21: {=IF(W21="","",IFERROR(OFFSET($BZ$11,0,MATCH($W21,$CA21:$FV21,0),),""))} | Z21: {=IF(W21="","",INDIRECT("'GRD-"&Y21&"'!$L$7"))} | AA21: {=IFERROR(OFFSET($BZ$11,ROW($B21)-11,MATCH(AA$10,$CA21:$FV21,0),),"")} | AB21: =IF(AA21="","",IF(VLOOKUP($B21,INDIRECT("'GRD-"&AC21&"'!$B:$R"),16,FALSE)="","",VLOOKUP($B21,INDIRECT("'GRD-"&AC21&"'!$B:$R"),16,FALSE))) | AC21: {=IF(AA21="","",IFERROR(OFFSET($BZ$11,0,MATCH($AA21,$CA21:$FV21,0),),""))} | AD21: {=IF(AA21="","",INDIRECT("'GRD-"&AC21&"'!$L$7"))} | AE21: {=IFERROR(OFFSET($BZ$11,ROW($B21)-11,MATCH(AE$10,$CA21:$FV21,0),),"")} | AF21: =IF(AE21="","",IF(VLOOKUP($B21,INDIRECT("'GRD-"&AG21&"'!$B:$R"),16,FALSE)="","",VLOOKUP($B21,INDIRECT("'GRD-"&AG21&"'!$B:$R"),16,FALSE))) | AG21: {=IF(AE21="","",IFERROR(OFFSET($BZ$11,0,MATCH($AE21,$CA21:$FV21,0),),""))} | AH21: {=IF(AE21="","",INDIRECT("'GRD-"&AG21&"'!$L$7"))} | AI21: {=IFERROR(OFFSET($BZ$11,ROW($B21)-11,MATCH(AI$10,$CA21:$FV21,0),),"")} | AJ21: =IF(AI21="","",IF(VLOOKUP($B21,INDIRECT("'GRD-"&AK21&"'!$B:$R"),16,FALSE)="","",VLOOKUP($B21,INDIRECT("'GRD-"&AK21&"'!$B:$R"),16,FALSE))) | AK21: {=IF(AI21="","",IFERROR(OFFSET($BZ$11,0,MATCH($AI21,$CA21:$FV21,0),),""))} | AL21: {=IF(AI21="","",INDIRECT("'GRD-"&AK21&"'!$L$7"))} | AM21: {=IFERROR(OFFSET($BZ$11,ROW($B21)-11,MATCH(AM$10,$CA21:$FV21,0),),"")} | AN21: =IF(AM21="","",IF(VLOOKUP($B21,INDIRECT("'GRD-"&AO21&"'!$B:$R"),16,FALSE)="","",VLOOKUP($B21,INDIRECT("'GRD-"&AO21&"'!$B:$R"),16,FALSE))) | AO21: {=IF(AM21="","",IFERROR(OFFSET($BZ$11,0,MATCH($AM21,$CA21:$FV21,0),),""))} | AP21: {=IF(AM21="","",INDIRECT("'GRD-"&AO21&"'!$L$7"))} | AQ21: {=IFERROR(OFFSET($BZ$11,ROW($B21)-11,MATCH(AQ$10,$CA21:$FV21,0),),"")} | AR21: =IF(AQ21="","",IF(VLOOKUP($B21,INDIRECT("'GRD-"&AS21&"'!$B:$R"),16,FALSE)="","",VLOOKUP($B21,INDIRECT("'GRD-"&AS21&"'!$B:$R"),16,FALSE))) | AS21: {=IF(AQ21="","",IFERROR(OFFSET($BZ$11,0,MATCH($AQ21,$CA21:$FV21,0),),""))} | AT21: {=IF(AQ21="","",INDIRECT("'GRD-"&AS21&"'!$L$7"))} | AU21: {=IFERROR(OFFSET($BZ$11,ROW($B21)-11,MATCH(AU$10,$CA21:$FV21,0),),"")} | AV21: =IF(AU21="","",IF(VLOOKUP($B21,INDIRECT("'GRD-"&AW21&"'!$B:$R"),16,FALSE)="","",VLOOKUP($B21,INDIRECT("'GRD-"&AW21&"'!$B:$R"),16,FALSE))) | AW21: {=IF(AU21="","",IFERROR(OFFSET($BZ$11,0,MATCH($AU21,$CA21:$FV21,0),),""))} | AX21: {=IF(AU21="","",INDIRECT("'GRD-"&AW21&"'!$L$7"))} | AY21: {=IFERROR(OFFSET($BZ$11,ROW($B21)-11,MATCH(AY$10,$CA21:$FV21,0),),"")} | AZ21: =IF(AY21="","",IF(VLOOKUP($B21,INDIRECT("'GRD-"&BA21&"'!$B:$R"),16,FALSE)="","",VLOOKUP($B21,INDIRECT("'GRD-"&BA21&"'!$B:$R"),16,FALSE))) | BA21: {=IF(AY21="","",IFERROR(OFFSET($BZ$11,0,MATCH($AY21,$CA21:$FV21,0),),""))} | BB21: {=IF(AY21="","",INDIRECT("'GRD-"&BA21&"'!$L$7"))} | BC21: {=IFERROR(OFFSET($BZ$11,ROW($B21)-11,MATCH(BC$10,$CA21:$FV21,0),),"")} | BD21: =IF(BC21="","",IF(VLOOKUP($B21,INDIRECT("'GRD-"&BE21&"'!$B:$R"),16,FALSE)="","",VLOOKUP($B21,INDIRECT("'GRD-"&BE21&"'!$B:$R"),16,FALSE))) | BE21: {=IF(BC21="","",IFERROR(OFFSET($BZ$11,0,MATCH($BC21,$CA21:$FV21,0),),""))} | BF21: {=IF(BC21="","",INDIRECT("'GRD-"&BE21&"'!$L$7"))} | CA21: =IFERROR(VLOOKUP($B21,INDIRECT("'GRD-"&CA$11&"'!B:R"),15,FALSE),"") | CB21: =IFERROR(VLOOKUP($B21,INDIRECT("'GRD-"&CB$11&"'!B:R"),15,FALSE),"") | CC21: =IFERROR(VLOOKUP($B21,INDIRECT("'GRD-"&CC$11&"'!B:R"),15,FALSE),"") | CD21: =IFERROR(VLOOKUP($B21,INDIRECT("'GRD-"&CD$11&"'!B:R"),15,FALSE),"") | CE21: =IFERROR(VLOOKUP($B21,INDIRECT("'GRD-"&CE$11&"'!B:R"),15,FALSE),"") | CF21: =IFERROR(VLOOKUP($B21,INDIRECT("'GRD-"&CF$11&"'!B:R"),15,FALSE),"") | CG21: =IFERROR(VLOOKUP($B21,INDIRECT("'GRD-"&CG$11&"'!B:R"),15,FALSE),"") | CH21: =IFERROR(VLOOKUP($B21,INDIRECT("'GRD-"&CH$11&"'!B:R"),15,FALSE),"") | ... FV21: =IFERROR(VLOOKUP($B21,INDIRECT("'GRD-"&FV$11&"'!B:R"),15,FALSE),"")
D22: =IF(K22="","",MAX($CA22:$FV22)) | E22: {=IF($K22="","",OFFSET($A$1,ROW($B22)-1,11+$D22*4,))} | F22: {=IF($K22="","",OFFSET($A$1,ROW($B22)-1,12+$D22*4,))} | G22: {=IF($K22="","",OFFSET($A$1,ROW($B22)-1,13+$D22*4,))} | J22: =IF(I22="A4",H22/8,IF(I22="A3",H22/4,IF(I22="A2",H22/2,IF(I22="A1",H22/1,IF(I22="A0",H22*2,""))))) | K22: {=IFERROR(OFFSET($BZ$11,ROW($B22)-11,MATCH(K$10,$CA22:$FV22,0),),"")} | L22: =IF(K22="","",IF(VLOOKUP($B22,INDIRECT("'GRD-"&M22&"'!$B:$R"),16,FALSE)="","",VLOOKUP($B22,INDIRECT("'GRD-"&M22&"'!$B:$R"),16,FALSE))) | M22: {=IF(K22="","",IFERROR(OFFSET($BZ$11,0,MATCH($K22,$CA22:$FV22,0),),""))} | N22: {=IF(K22="","",INDIRECT("'GRD-"&M22&"'!$L$7"))} | O22: {=IFERROR(OFFSET($BZ$11,ROW($B22)-11,MATCH(O$10,$CA22:$FV22,0),),"")} | P22: =IF(O22="","",IF(VLOOKUP($B22,INDIRECT("'GRD-"&Q22&"'!$B:$R"),16,FALSE)="","",VLOOKUP($B22,INDIRECT("'GRD-"&Q22&"'!$B:$R"),16,FALSE))) | Q22: {=IF(O22="","",IFERROR(OFFSET($BZ$11,0,MATCH($O22,$CA22:$FV22,0),),""))} | R22: {=IF(O22="","",INDIRECT("'GRD-"&Q22&"'!$L$7"))} | S22: {=IFERROR(OFFSET($BZ$11,ROW($B22)-11,MATCH(S$10,$CA22:$FV22,0),),"")} | T22: =IF(S22="","",IF(VLOOKUP($B22,INDIRECT("'GRD-"&U22&"'!$B:$R"),16,FALSE)="","",VLOOKUP($B22,INDIRECT("'GRD-"&U22&"'!$B:$R"),16,FALSE))) | U22: {=IF(S22="","",IFERROR(OFFSET($BZ$11,0,MATCH($S22,$CA22:$FV22,0),),""))} | V22: {=IF(S22="","",INDIRECT("'GRD-"&U22&"'!$L$7"))} | W22: {=IFERROR(OFFSET($BZ$11,ROW($B22)-11,MATCH(W$10,$CA22:$FV22,0),),"")} | X22: =IF(W22="","",IF(VLOOKUP($B22,INDIRECT("'GRD-"&Y22&"'!$B:$R"),16,FALSE)="","",VLOOKUP($B22,INDIRECT("'GRD-"&Y22&"'!$B:$R"),16,FALSE))) | Y22: {=IF(W22="","",IFERROR(OFFSET($BZ$11,0,MATCH($W22,$CA22:$FV22,0),),""))} | Z22: {=IF(W22="","",INDIRECT("'GRD-"&Y22&"'!$L$7"))} | AA22: {=IFERROR(OFFSET($BZ$11,ROW($B22)-11,MATCH(AA$10,$CA22:$FV22,0),),"")} | AB22: =IF(AA22="","",IF(VLOOKUP($B22,INDIRECT("'GRD-"&AC22&"'!$B:$R"),16,FALSE)="","",VLOOKUP($B22,INDIRECT("'GRD-"&AC22&"'!$B:$R"),16,FALSE))) | AC22: {=IF(AA22="","",IFERROR(OFFSET($BZ$11,0,MATCH($AA22,$CA22:$FV22,0),),""))} | AD22: {=IF(AA22="","",INDIRECT("'GRD-"&AC22&"'!$L$7"))} | AE22: {=IFERROR(OFFSET($BZ$11,ROW($B22)-11,MATCH(AE$10,$CA22:$FV22,0),),"")} | AF22: =IF(AE22="","",IF(VLOOKUP($B22,INDIRECT("'GRD-"&AG22&"'!$B:$R"),16,FALSE)="","",VLOOKUP($B22,INDIRECT("'GRD-"&AG22&"'!$B:$R"),16,FALSE))) | AG22: {=IF(AE22="","",IFERROR(OFFSET($BZ$11,0,MATCH($AE22,$CA22:$FV22,0),),""))} | AH22: {=IF(AE22="","",INDIRECT("'GRD-"&AG22&"'!$L$7"))} | AI22: {=IFERROR(OFFSET($BZ$11,ROW($B22)-11,MATCH(AI$10,$CA22:$FV22,0),),"")} | AJ22: =IF(AI22="","",IF(VLOOKUP($B22,INDIRECT("'GRD-"&AK22&"'!$B:$R"),16,FALSE)="","",VLOOKUP($B22,INDIRECT("'GRD-"&AK22&"'!$B:$R"),16,FALSE))) | AK22: {=IF(AI22="","",IFERROR(OFFSET($BZ$11,0,MATCH($AI22,$CA22:$FV22,0),),""))} | AL22: {=IF(AI22="","",INDIRECT("'GRD-"&AK22&"'!$L$7"))} | AM22: {=IFERROR(OFFSET($BZ$11,ROW($B22)-11,MATCH(AM$10,$CA22:$FV22,0),),"")} | AN22: =IF(AM22="","",IF(VLOOKUP($B22,INDIRECT("'GRD-"&AO22&"'!$B:$R"),16,FALSE)="","",VLOOKUP($B22,INDIRECT("'GRD-"&AO22&"'!$B:$R"),16,FALSE))) | AO22: {=IF(AM22="","",IFERROR(OFFSET($BZ$11,0,MATCH($AM22,$CA22:$FV22,0),),""))} | AP22: {=IF(AM22="","",INDIRECT("'GRD-"&AO22&"'!$L$7"))} | AQ22: {=IFERROR(OFFSET($BZ$11,ROW($B22)-11,MATCH(AQ$10,$CA22:$FV22,0),),"")} | AR22: =IF(AQ22="","",IF(VLOOKUP($B22,INDIRECT("'GRD-"&AS22&"'!$B:$R"),16,FALSE)="","",VLOOKUP($B22,INDIRECT("'GRD-"&AS22&"'!$B:$R"),16,FALSE))) | AS22: {=IF(AQ22="","",IFERROR(OFFSET($BZ$11,0,MATCH($AQ22,$CA22:$FV22,0),),""))} | AT22: {=IF(AQ22="","",INDIRECT("'GRD-"&AS22&"'!$L$7"))} | AU22: {=IFERROR(OFFSET($BZ$11,ROW($B22)-11,MATCH(AU$10,$CA22:$FV22,0),),"")} | AV22: =IF(AU22="","",IF(VLOOKUP($B22,INDIRECT("'GRD-"&AW22&"'!$B:$R"),16,FALSE)="","",VLOOKUP($B22,INDIRECT("'GRD-"&AW22&"'!$B:$R"),16,FALSE))) | AW22: {=IF(AU22="","",IFERROR(OFFSET($BZ$11,0,MATCH($AU22,$CA22:$FV22,0),),""))} | AX22: {=IF(AU22="","",INDIRECT("'GRD-"&AW22&"'!$L$7"))} | AY22: {=IFERROR(OFFSET($BZ$11,ROW($B22)-11,MATCH(AY$10,$CA22:$FV22,0),),"")} | AZ22: =IF(AY22="","",IF(VLOOKUP($B22,INDIRECT("'GRD-"&BA22&"'!$B:$R"),16,FALSE)="","",VLOOKUP($B22,INDIRECT("'GRD-"&BA22&"'!$B:$R"),16,FALSE))) | BA22: {=IF(AY22="","",IFERROR(OFFSET($BZ$11,0,MATCH($AY22,$CA22:$FV22,0),),""))} | BB22: {=IF(AY22="","",INDIRECT("'GRD-"&BA22&"'!$L$7"))} | BC22: {=IFERROR(OFFSET($BZ$11,ROW($B22)-11,MATCH(BC$10,$CA22:$FV22,0),),"")} | BD22: =IF(BC22="","",IF(VLOOKUP($B22,INDIRECT("'GRD-"&BE22&"'!$B:$R"),16,FALSE)="","",VLOOKUP($B22,INDIRECT("'GRD-"&BE22&"'!$B:$R"),16,FALSE))) | BE22: {=IF(BC22="","",IFERROR(OFFSET($BZ$11,0,MATCH($BC22,$CA22:$FV22,0),),""))} | BF22: {=IF(BC22="","",INDIRECT("'GRD-"&BE22&"'!$L$7"))} | CA22: =IFERROR(VLOOKUP($B22,INDIRECT("'GRD-"&CA$11&"'!B:R"),15,FALSE),"") | CB22: =IFERROR(VLOOKUP($B22,INDIRECT("'GRD-"&CB$11&"'!B:R"),15,FALSE),"") | CC22: =IFERROR(VLOOKUP($B22,INDIRECT("'GRD-"&CC$11&"'!B:R"),15,FALSE),"") | CD22: =IFERROR(VLOOKUP($B22,INDIRECT("'GRD-"&CD$11&"'!B:R"),15,FALSE),"") | CE22: =IFERROR(VLOOKUP($B22,INDIRECT("'GRD-"&CE$11&"'!B:R"),15,FALSE),"") | CF22: =IFERROR(VLOOKUP($B22,INDIRECT("'GRD-"&CF$11&"'!B:R"),15,FALSE),"") | CG22: =IFERROR(VLOOKUP($B22,INDIRECT("'GRD-"&CG$11&"'!B:R"),15,FALSE),"") | CH22: =IFERROR(VLOOKUP($B22,INDIRECT("'GRD-"&CH$11&"'!B:R"),15,FALSE),"") | ... FV22: =IFERROR(VLOOKUP($B22,INDIRECT("'GRD-"&FV$11&"'!B:R"),15,FALSE),"")
D23: =IF(K23="","",MAX($CA23:$FV23)) | E23: {=IF($K23="","",OFFSET($A$1,ROW($B23)-1,11+$D23*4,))} | F23: {=IF($K23="","",OFFSET($A$1,ROW($B23)-1,12+$D23*4,))} | G23: {=IF($K23="","",OFFSET($A$1,ROW($B23)-1,13+$D23*4,))} | J23: =IF(I23="A4",H23/8,IF(I23="A3",H23/4,IF(I23="A2",H23/2,IF(I23="A1",H23/1,IF(I23="A0",H23*2,""))))) | K23: {=IFERROR(OFFSET($BZ$11,ROW($B23)-11,MATCH(K$10,$CA23:$FV23,0),),"")} | L23: =IF(K23="","",IF(VLOOKUP($B23,INDIRECT("'GRD-"&M23&"'!$B:$R"),16,FALSE)="","",VLOOKUP($B23,INDIRECT("'GRD-"&M23&"'!$B:$R"),16,FALSE))) | M23: {=IF(K23="","",IFERROR(OFFSET($BZ$11,0,MATCH($K23,$CA23:$FV23,0),),""))} | N23: {=IF(K23="","",INDIRECT("'GRD-"&M23&"'!$L$7"))} | O23: {=IFERROR(OFFSET($BZ$11,ROW($B23)-11,MATCH(O$10,$CA23:$FV23,0),),"")} | P23: =IF(O23="","",IF(VLOOKUP($B23,INDIRECT("'GRD-"&Q23&"'!$B:$R"),16,FALSE)="","",VLOOKUP($B23,INDIRECT("'GRD-"&Q23&"'!$B:$R"),16,FALSE))) | Q23: {=IF(O23="","",IFERROR(OFFSET($BZ$11,0,MATCH($O23,$CA23:$FV23,0),),""))} | R23: {=IF(O23="","",INDIRECT("'GRD-"&Q23&"'!$L$7"))} | S23: {=IFERROR(OFFSET($BZ$11,ROW($B23)-11,MATCH(S$10,$CA23:$FV23,0),),"")} | T23: =IF(S23="","",IF(VLOOKUP($B23,INDIRECT("'GRD-"&U23&"'!$B:$R"),16,FALSE)="","",VLOOKUP($B23,INDIRECT("'GRD-"&U23&"'!$B:$R"),16,FALSE))) | U23: {=IF(S23="","",IFERROR(OFFSET($BZ$11,0,MATCH($S23,$CA23:$FV23,0),),""))} | V23: {=IF(S23="","",INDIRECT("'GRD-"&U23&"'!$L$7"))} | W23: {=IFERROR(OFFSET($BZ$11,ROW($B23)-11,MATCH(W$10,$CA23:$FV23,0),),"")} | X23: =IF(W23="","",IF(VLOOKUP($B23,INDIRECT("'GRD-"&Y23&"'!$B:$R"),16,FALSE)="","",VLOOKUP($B23,INDIRECT("'GRD-"&Y23&"'!$B:$R"),16,FALSE))) | Y23: {=IF(W23="","",IFERROR(OFFSET($BZ$11,0,MATCH($W23,$CA23:$FV23,0),),""))} | Z23: {=IF(W23="","",INDIRECT("'GRD-"&Y23&"'!$L$7"))} | AA23: {=IFERROR(OFFSET($BZ$11,ROW($B23)-11,MATCH(AA$10,$CA23:$FV23,0),),"")} | AB23: =IF(AA23="","",IF(VLOOKUP($B23,INDIRECT("'GRD-"&AC23&"'!$B:$R"),16,FALSE)="","",VLOOKUP($B23,INDIRECT("'GRD-"&AC23&"'!$B:$R"),16,FALSE))) | AC23: {=IF(AA23="","",IFERROR(OFFSET($BZ$11,0,MATCH($AA23,$CA23:$FV23,0),),""))} | AD23: {=IF(AA23="","",INDIRECT("'GRD-"&AC23&"'!$L$7"))} | AE23: {=IFERROR(OFFSET($BZ$11,ROW($B23)-11,MATCH(AE$10,$CA23:$FV23,0),),"")} | AF23: =IF(AE23="","",IF(VLOOKUP($B23,INDIRECT("'GRD-"&AG23&"'!$B:$R"),16,FALSE)="","",VLOOKUP($B23,INDIRECT("'GRD-"&AG23&"'!$B:$R"),16,FALSE))) | AG23: {=IF(AE23="","",IFERROR(OFFSET($BZ$11,0,MATCH($AE23,$CA23:$FV23,0),),""))} | AH23: {=IF(AE23="","",INDIRECT("'GRD-"&AG23&"'!$L$7"))} | AI23: {=IFERROR(OFFSET($BZ$11,ROW($B23)-11,MATCH(AI$10,$CA23:$FV23,0),),"")} | AJ23: =IF(AI23="","",IF(VLOOKUP($B23,INDIRECT("'GRD-"&AK23&"'!$B:$R"),16,FALSE)="","",VLOOKUP($B23,INDIRECT("'GRD-"&AK23&"'!$B:$R"),16,FALSE))) | AK23: {=IF(AI23="","",IFERROR(OFFSET($BZ$11,0,MATCH($AI23,$CA23:$FV23,0),),""))} | AL23: {=IF(AI23="","",INDIRECT("'GRD-"&AK23&"'!$L$7"))} | AM23: {=IFERROR(OFFSET($BZ$11,ROW($B23)-11,MATCH(AM$10,$CA23:$FV23,0),),"")} | AN23: =IF(AM23="","",IF(VLOOKUP($B23,INDIRECT("'GRD-"&AO23&"'!$B:$R"),16,FALSE)="","",VLOOKUP($B23,INDIRECT("'GRD-"&AO23&"'!$B:$R"),16,FALSE))) | AO23: {=IF(AM23="","",IFERROR(OFFSET($BZ$11,0,MATCH($AM23,$CA23:$FV23,0),),""))} | AP23: {=IF(AM23="","",INDIRECT("'GRD-"&AO23&"'!$L$7"))} | AQ23: {=IFERROR(OFFSET($BZ$11,ROW($B23)-11,MATCH(AQ$10,$CA23:$FV23,0),),"")} | AR23: =IF(AQ23="","",IF(VLOOKUP($B23,INDIRECT("'GRD-"&AS23&"'!$B:$R"),16,FALSE)="","",VLOOKUP($B23,INDIRECT("'GRD-"&AS23&"'!$B:$R"),16,FALSE))) | AS23: {=IF(AQ23="","",IFERROR(OFFSET($BZ$11,0,MATCH($AQ23,$CA23:$FV23,0),),""))} | AT23: {=IF(AQ23="","",INDIRECT("'GRD-"&AS23&"'!$L$7"))} | AU23: {=IFERROR(OFFSET($BZ$11,ROW($B23)-11,MATCH(AU$10,$CA23:$FV23,0),),"")} | AV23: =IF(AU23="","",IF(VLOOKUP($B23,INDIRECT("'GRD-"&AW23&"'!$B:$R"),16,FALSE)="","",VLOOKUP($B23,INDIRECT("'GRD-"&AW23&"'!$B:$R"),16,FALSE))) | AW23: {=IF(AU23="","",IFERROR(OFFSET($BZ$11,0,MATCH($AU23,$CA23:$FV23,0),),""))} | AX23: {=IF(AU23="","",INDIRECT("'GRD-"&AW23&"'!$L$7"))} | AY23: {=IFERROR(OFFSET($BZ$11,ROW($B23)-11,MATCH(AY$10,$CA23:$FV23,0),),"")} | AZ23: =IF(AY23="","",IF(VLOOKUP($B23,INDIRECT("'GRD-"&BA23&"'!$B:$R"),16,FALSE)="","",VLOOKUP($B23,INDIRECT("'GRD-"&BA23&"'!$B:$R"),16,FALSE))) | BA23: {=IF(AY23="","",IFERROR(OFFSET($BZ$11,0,MATCH($AY23,$CA23:$FV23,0),),""))} | BB23: {=IF(AY23="","",INDIRECT("'GRD-"&BA23&"'!$L$7"))} | BC23: {=IFERROR(OFFSET($BZ$11,ROW($B23)-11,MATCH(BC$10,$CA23:$FV23,0),),"")} | BD23: =IF(BC23="","",IF(VLOOKUP($B23,INDIRECT("'GRD-"&BE23&"'!$B:$R"),16,FALSE)="","",VLOOKUP($B23,INDIRECT("'GRD-"&BE23&"'!$B:$R"),16,FALSE))) | BE23: {=IF(BC23="","",IFERROR(OFFSET($BZ$11,0,MATCH($BC23,$CA23:$FV23,0),),""))} | BF23: {=IF(BC23="","",INDIRECT("'GRD-"&BE23&"'!$L$7"))} | CA23: =IFERROR(VLOOKUP($B23,INDIRECT("'GRD-"&CA$11&"'!B:R"),15,FALSE),"") | CB23: =IFERROR(VLOOKUP($B23,INDIRECT("'GRD-"&CB$11&"'!B:R"),15,FALSE),"") | CC23: =IFERROR(VLOOKUP($B23,INDIRECT("'GRD-"&CC$11&"'!B:R"),15,FALSE),"") | CD23: =IFERROR(VLOOKUP($B23,INDIRECT("'GRD-"&CD$11&"'!B:R"),15,FALSE),"") | CE23: =IFERROR(VLOOKUP($B23,INDIRECT("'GRD-"&CE$11&"'!B:R"),15,FALSE),"") | CF23: =IFERROR(VLOOKUP($B23,INDIRECT("'GRD-"&CF$11&"'!B:R"),15,FALSE),"") | CG23: =IFERROR(VLOOKUP($B23,INDIRECT("'GRD-"&CG$11&"'!B:R"),15,FALSE),"") | CH23: =IFERROR(VLOOKUP($B23,INDIRECT("'GRD-"&CH$11&"'!B:R"),15,FALSE),"") | ... FV23: =IFERROR(VLOOKUP($B23,INDIRECT("'GRD-"&FV$11&"'!B:R"),15,FALSE),"")
